*** Starting uWSGI 2.0.25.1 (64bit) on [Sat May 25 00:40:39 2024] ***
compiled with version: 11.2.0 on 24 May 2024 14:41:03
os: Linux-5.15.0-86-generic #96-Ubuntu SMP Wed Sep 20 08:23:49 UTC 2023
nodename: VM-8-9-ubuntu
machine: x86_64
clock source: unix
detected number of CPU cores: 2
current working directory: /home/ubuntu/seProject/SEGroup6/猫猫就诊/Project
writing pidfile to uwsgi.pid
detected binary path: /usr/local/bin/uwsgi
!!! no internal routing support, rebuild with pcre support !!!
chdir() to /home/ubuntu/seProject/SEGroup6/猫猫就诊/Project
your processes number limit is 7402
your memory page size is 4096 bytes
detected max file descriptor number: 1024
lock engine: pthread robust mutexes
thunder lock: disabled (you can enable it with --thunder-lock)
uwsgi socket 0 bound to TCP address 127.0.0.1:5000 fd 3
Python version: 3.10.12 (main, Jun 11 2023, 05:26:28) [GCC 11.4.0]
Python main interpreter initialized at 0x55ccf0b125f0
python threads support enabled
your server socket listen backlog is limited to 100 connections
your mercy for graceful operations on workers is 60 seconds
mapped 1031270 bytes (1007 KB) for 8 cores
*** Operational MODE: preforking+threaded ***
WSGI app 0 (mountpoint='') ready in 1 seconds on interpreter 0x55ccf0b125f0 pid: 69355 (default app)
*** uWSGI is running in multiple interpreter mode ***
spawned uWSGI master process (pid: 69355)
spawned uWSGI worker 1 (pid: 69359, cores: 2)
spawned uWSGI worker 2 (pid: 69360, cores: 2)
spawned uWSGI worker 3 (pid: 69362, cores: 2)
spawned uWSGI worker 4 (pid: 69363, cores: 2)
SIGINT/SIGTERM received...killing workers...
worker 1 buried after 1 seconds
worker 2 buried after 1 seconds
worker 3 buried after 1 seconds
worker 4 buried after 1 seconds
goodbye to uWSGI.
VACUUM: pidfile removed.
*** Starting uWSGI 2.0.25.1 (64bit) on [Sat May 25 00:42:16 2024] ***
compiled with version: 11.2.0 on 24 May 2024 14:41:03
os: Linux-5.15.0-86-generic #96-Ubuntu SMP Wed Sep 20 08:23:49 UTC 2023
nodename: VM-8-9-ubuntu
machine: x86_64
clock source: unix
detected number of CPU cores: 2
current working directory: /home/ubuntu/seProject/SEGroup6/猫猫就诊/Project
writing pidfile to uwsgi.pid
detected binary path: /usr/local/bin/uwsgi
!!! no internal routing support, rebuild with pcre support !!!
chdir() to /home/ubuntu/seProject/SEGroup6/猫猫就诊/Project
your processes number limit is 7402
your memory page size is 4096 bytes
detected max file descriptor number: 1024
lock engine: pthread robust mutexes
thunder lock: disabled (you can enable it with --thunder-lock)
uwsgi socket 0 bound to TCP address 127.0.0.1:5000 fd 3
Python version: 3.10.12 (main, Jun 11 2023, 05:26:28) [GCC 11.4.0]
Python main interpreter initialized at 0x555dd3fa85f0
python threads support enabled
your server socket listen backlog is limited to 100 connections
your mercy for graceful operations on workers is 60 seconds
mapped 1031270 bytes (1007 KB) for 8 cores
*** Operational MODE: preforking+threaded ***
WSGI app 0 (mountpoint='') ready in 1 seconds on interpreter 0x555dd3fa85f0 pid: 69867 (default app)
*** uWSGI is running in multiple interpreter mode ***
spawned uWSGI master process (pid: 69867)
spawned uWSGI worker 1 (pid: 69868, cores: 2)
spawned uWSGI worker 2 (pid: 69869, cores: 2)
spawned uWSGI worker 3 (pid: 69871, cores: 2)
spawned uWSGI worker 4 (pid: 69872, cores: 2)
SIGINT/SIGTERM received...killing workers...
worker 1 buried after 1 seconds
worker 2 buried after 1 seconds
worker 3 buried after 1 seconds
worker 4 buried after 1 seconds
goodbye to uWSGI.
VACUUM: pidfile removed.
*** Starting uWSGI 2.0.25.1 (64bit) on [Sat May 25 01:00:05 2024] ***
compiled with version: 11.2.0 on 24 May 2024 14:41:03
os: Linux-5.15.0-86-generic #96-Ubuntu SMP Wed Sep 20 08:23:49 UTC 2023
nodename: VM-8-9-ubuntu
machine: x86_64
clock source: unix
detected number of CPU cores: 2
current working directory: /home/ubuntu/seProject/SEGroup6/猫猫就诊/Project
writing pidfile to uwsgi.pid
detected binary path: /usr/local/bin/uwsgi
!!! no internal routing support, rebuild with pcre support !!!
chdir() to /home/ubuntu/seProject/SEGroup6/猫猫就诊/Project
your processes number limit is 7402
your memory page size is 4096 bytes
detected max file descriptor number: 1024
lock engine: pthread robust mutexes
thunder lock: disabled (you can enable it with --thunder-lock)
uwsgi socket 0 bound to TCP address 127.0.0.1:5000 fd 3
Python version: 3.10.12 (main, Jun 11 2023, 05:26:28) [GCC 11.4.0]
Python main interpreter initialized at 0x55f3cc9925f0
python threads support enabled
your server socket listen backlog is limited to 100 connections
your mercy for graceful operations on workers is 60 seconds
mapped 1031270 bytes (1007 KB) for 8 cores
*** Operational MODE: preforking+threaded ***
WSGI app 0 (mountpoint='') ready in 0 seconds on interpreter 0x55f3cc9925f0 pid: 75514 (default app)
*** uWSGI is running in multiple interpreter mode ***
spawned uWSGI master process (pid: 75514)
spawned uWSGI worker 1 (pid: 75515, cores: 2)
spawned uWSGI worker 2 (pid: 75516, cores: 2)
spawned uWSGI worker 3 (pid: 75518, cores: 2)
spawned uWSGI worker 4 (pid: 75519, cores: 2)
Invalid HTTP_HOST header: '101.42.36.160'. You may need to add '101.42.36.160' to ALLOWED_HOSTS.
Traceback (most recent call last):
  File "/home/ubuntu/.local/lib/python3.10/site-packages/django/core/handlers/exception.py", line 55, in inner
    response = get_response(request)
  File "/home/ubuntu/.local/lib/python3.10/site-packages/django/utils/deprecation.py", line 133, in __call__
    response = self.process_request(request)
  File "/home/ubuntu/.local/lib/python3.10/site-packages/django/middleware/common.py", line 48, in process_request
    host = request.get_host()
  File "/home/ubuntu/.local/lib/python3.10/site-packages/django/http/request.py", line 151, in get_host
    raise DisallowedHost(msg)
django.core.exceptions.DisallowedHost: Invalid HTTP_HOST header: '101.42.36.160'. You may need to add '101.42.36.160' to ALLOWED_HOSTS.
Bad Request: /api/treatments/list/
[pid: 75519|app: 0|req: 1/1] 219.239.227.188 () {38 vars in 651 bytes} [Fri May 24 17:00:09 2024] GET /api/treatments/list/ => generated 58477 bytes in 192 msecs (HTTP/1.1 400) 5 headers in 186 bytes (1 switches on core 0)
*** Starting uWSGI 2.0.25.1 (64bit) on [Sat May 25 01:04:04 2024] ***
compiled with version: 11.2.0 on 24 May 2024 14:41:03
os: Linux-5.15.0-86-generic #96-Ubuntu SMP Wed Sep 20 08:23:49 UTC 2023
nodename: VM-8-9-ubuntu
machine: x86_64
clock source: unix
detected number of CPU cores: 2
current working directory: /home/ubuntu/seProject/SEGroup6/猫猫就诊/Project
writing pidfile to uwsgi.pid
detected binary path: /usr/local/bin/uwsgi
!!! no internal routing support, rebuild with pcre support !!!
chdir() to /home/ubuntu/seProject/SEGroup6/猫猫就诊/Project
your processes number limit is 7402
your memory page size is 4096 bytes
detected max file descriptor number: 1024
lock engine: pthread robust mutexes
thunder lock: disabled (you can enable it with --thunder-lock)
uwsgi socket 0 bound to TCP address 127.0.0.1:8000 fd 3
Python version: 3.10.12 (main, Jun 11 2023, 05:26:28) [GCC 11.4.0]
Python main interpreter initialized at 0x55f33cfb55f0
python threads support enabled
your server socket listen backlog is limited to 100 connections
your mercy for graceful operations on workers is 60 seconds
mapped 1031270 bytes (1007 KB) for 8 cores
*** Operational MODE: preforking+threaded ***
WSGI app 0 (mountpoint='') ready in 0 seconds on interpreter 0x55f33cfb55f0 pid: 76756 (default app)
*** uWSGI is running in multiple interpreter mode ***
spawned uWSGI master process (pid: 76756)
spawned uWSGI worker 1 (pid: 76757, cores: 2)
spawned uWSGI worker 2 (pid: 76758, cores: 2)
spawned uWSGI worker 3 (pid: 76760, cores: 2)
spawned uWSGI worker 4 (pid: 76761, cores: 2)
Invalid HTTP_HOST header: '101.42.36.160'. You may need to add '101.42.36.160' to ALLOWED_HOSTS.
Traceback (most recent call last):
  File "/home/ubuntu/.local/lib/python3.10/site-packages/django/core/handlers/exception.py", line 55, in inner
    response = get_response(request)
  File "/home/ubuntu/.local/lib/python3.10/site-packages/django/utils/deprecation.py", line 133, in __call__
    response = self.process_request(request)
  File "/home/ubuntu/.local/lib/python3.10/site-packages/django/middleware/common.py", line 48, in process_request
    host = request.get_host()
  File "/home/ubuntu/.local/lib/python3.10/site-packages/django/http/request.py", line 151, in get_host
    raise DisallowedHost(msg)
django.core.exceptions.DisallowedHost: Invalid HTTP_HOST header: '101.42.36.160'. You may need to add '101.42.36.160' to ALLOWED_HOSTS.
Bad Request: /api/treatments/list/
[pid: 76758|app: 0|req: 1/1] 219.239.227.188 () {38 vars in 651 bytes} [Fri May 24 17:04:25 2024] GET /api/treatments/list/ => generated 58477 bytes in 78 msecs (HTTP/1.1 400) 5 headers in 186 bytes (1 switches on core 0)
Invalid HTTP_HOST header: '101.42.36.160'. You may need to add '101.42.36.160' to ALLOWED_HOSTS.
Traceback (most recent call last):
  File "/home/ubuntu/.local/lib/python3.10/site-packages/django/core/handlers/exception.py", line 55, in inner
    response = get_response(request)
  File "/home/ubuntu/.local/lib/python3.10/site-packages/django/utils/deprecation.py", line 133, in __call__
    response = self.process_request(request)
  File "/home/ubuntu/.local/lib/python3.10/site-packages/django/middleware/common.py", line 48, in process_request
    host = request.get_host()
  File "/home/ubuntu/.local/lib/python3.10/site-packages/django/http/request.py", line 151, in get_host
    raise DisallowedHost(msg)
django.core.exceptions.DisallowedHost: Invalid HTTP_HOST header: '101.42.36.160'. You may need to add '101.42.36.160' to ALLOWED_HOSTS.
Bad Request: /api/treatments/list/
[pid: 76758|app: 0|req: 2/2] 219.239.227.188 () {38 vars in 651 bytes} [Fri May 24 17:06:52 2024] GET /api/treatments/list/ => generated 58477 bytes in 19 msecs (HTTP/1.1 400) 5 headers in 186 bytes (1 switches on core 1)
*** Starting uWSGI 2.0.25.1 (64bit) on [Sat May 25 01:10:54 2024] ***
compiled with version: 11.2.0 on 24 May 2024 14:41:03
os: Linux-5.15.0-86-generic #96-Ubuntu SMP Wed Sep 20 08:23:49 UTC 2023
nodename: VM-8-9-ubuntu
machine: x86_64
clock source: unix
detected number of CPU cores: 2
current working directory: /home/ubuntu/seProject/SEGroup6/猫猫就诊/Project
writing pidfile to uwsgi.pid
detected binary path: /usr/local/bin/uwsgi
!!! no internal routing support, rebuild with pcre support !!!
chdir() to /home/ubuntu/seProject/SEGroup6/猫猫就诊/Project
your processes number limit is 7402
your memory page size is 4096 bytes
detected max file descriptor number: 1024
lock engine: pthread robust mutexes
thunder lock: disabled (you can enable it with --thunder-lock)
probably another instance of uWSGI is running on the same address (127.0.0.1:8000).
bind(): Address already in use [core/socket.c line 769]
Invalid HTTP_HOST header: '101.42.36.160'. You may need to add '101.42.36.160' to ALLOWED_HOSTS.
Traceback (most recent call last):
  File "/home/ubuntu/.local/lib/python3.10/site-packages/django/core/handlers/exception.py", line 55, in inner
    response = get_response(request)
  File "/home/ubuntu/.local/lib/python3.10/site-packages/django/utils/deprecation.py", line 133, in __call__
    response = self.process_request(request)
  File "/home/ubuntu/.local/lib/python3.10/site-packages/django/middleware/common.py", line 48, in process_request
    host = request.get_host()
  File "/home/ubuntu/.local/lib/python3.10/site-packages/django/http/request.py", line 151, in get_host
    raise DisallowedHost(msg)
django.core.exceptions.DisallowedHost: Invalid HTTP_HOST header: '101.42.36.160'. You may need to add '101.42.36.160' to ALLOWED_HOSTS.
Bad Request: /api/treatments/list/
[pid: 76760|app: 0|req: 1/3] 219.239.227.188 () {38 vars in 651 bytes} [Fri May 24 17:11:12 2024] GET /api/treatments/list/ => generated 58477 bytes in 130 msecs (HTTP/1.1 400) 5 headers in 186 bytes (1 switches on core 0)
Invalid HTTP_HOST header: '101.42.36.160'. You may need to add '101.42.36.160' to ALLOWED_HOSTS.
Traceback (most recent call last):
  File "/home/ubuntu/.local/lib/python3.10/site-packages/django/core/handlers/exception.py", line 55, in inner
    response = get_response(request)
  File "/home/ubuntu/.local/lib/python3.10/site-packages/django/utils/deprecation.py", line 133, in __call__
    response = self.process_request(request)
  File "/home/ubuntu/.local/lib/python3.10/site-packages/django/middleware/common.py", line 48, in process_request
    host = request.get_host()
  File "/home/ubuntu/.local/lib/python3.10/site-packages/django/http/request.py", line 151, in get_host
    raise DisallowedHost(msg)
django.core.exceptions.DisallowedHost: Invalid HTTP_HOST header: '101.42.36.160'. You may need to add '101.42.36.160' to ALLOWED_HOSTS.
Bad Request: /api/treatments/list/
[pid: 76760|app: 0|req: 2/4] 219.239.227.188 () {38 vars in 739 bytes} [Fri May 24 17:11:21 2024] GET /api/treatments/list/ => generated 58565 bytes in 19 msecs (HTTP/1.1 400) 5 headers in 186 bytes (1 switches on core 1)
Invalid HTTP_HOST header: '101.42.36.160'. You may need to add '101.42.36.160' to ALLOWED_HOSTS.
Traceback (most recent call last):
  File "/home/ubuntu/.local/lib/python3.10/site-packages/django/core/handlers/exception.py", line 55, in inner
    response = get_response(request)
  File "/home/ubuntu/.local/lib/python3.10/site-packages/django/utils/deprecation.py", line 133, in __call__
    response = self.process_request(request)
  File "/home/ubuntu/.local/lib/python3.10/site-packages/django/middleware/common.py", line 48, in process_request
    host = request.get_host()
  File "/home/ubuntu/.local/lib/python3.10/site-packages/django/http/request.py", line 151, in get_host
    raise DisallowedHost(msg)
django.core.exceptions.DisallowedHost: Invalid HTTP_HOST header: '101.42.36.160'. You may need to add '101.42.36.160' to ALLOWED_HOSTS.
Bad Request: /api/treatments/list/
[pid: 76760|app: 0|req: 3/5] 219.239.227.188 () {38 vars in 651 bytes} [Fri May 24 17:12:52 2024] GET /api/treatments/list/ => generated 58477 bytes in 20 msecs (HTTP/1.1 400) 5 headers in 186 bytes (1 switches on core 0)
Invalid HTTP_HOST header: '101.42.36.160'. You may need to add '101.42.36.160' to ALLOWED_HOSTS.
Traceback (most recent call last):
  File "/home/ubuntu/.local/lib/python3.10/site-packages/django/core/handlers/exception.py", line 55, in inner
    response = get_response(request)
  File "/home/ubuntu/.local/lib/python3.10/site-packages/django/utils/deprecation.py", line 133, in __call__
    response = self.process_request(request)
  File "/home/ubuntu/.local/lib/python3.10/site-packages/django/middleware/common.py", line 48, in process_request
    host = request.get_host()
  File "/home/ubuntu/.local/lib/python3.10/site-packages/django/http/request.py", line 151, in get_host
    raise DisallowedHost(msg)
django.core.exceptions.DisallowedHost: Invalid HTTP_HOST header: '101.42.36.160'. You may need to add '101.42.36.160' to ALLOWED_HOSTS.
Bad Request: /api/treatments/list/
[pid: 76760|app: 0|req: 4/6] 219.239.227.188 () {40 vars in 770 bytes} [Fri May 24 17:13:47 2024] GET /api/treatments/list/ => generated 58702 bytes in 19 msecs (HTTP/1.1 400) 5 headers in 186 bytes (1 switches on core 1)
Invalid HTTP_HOST header: '101.42.36.160'. You may need to add '101.42.36.160' to ALLOWED_HOSTS.
Traceback (most recent call last):
  File "/home/ubuntu/.local/lib/python3.10/site-packages/django/core/handlers/exception.py", line 55, in inner
    response = get_response(request)
  File "/home/ubuntu/.local/lib/python3.10/site-packages/django/utils/deprecation.py", line 133, in __call__
    response = self.process_request(request)
  File "/home/ubuntu/.local/lib/python3.10/site-packages/django/middleware/common.py", line 48, in process_request
    host = request.get_host()
  File "/home/ubuntu/.local/lib/python3.10/site-packages/django/http/request.py", line 151, in get_host
    raise DisallowedHost(msg)
django.core.exceptions.DisallowedHost: Invalid HTTP_HOST header: '101.42.36.160'. You may need to add '101.42.36.160' to ALLOWED_HOSTS.
Bad Request: /api/treatments/list/
[pid: 76761|app: 0|req: 1/7] 219.239.227.188 () {40 vars in 770 bytes} [Fri May 24 17:13:49 2024] GET /api/treatments/list/ => generated 58702 bytes in 74 msecs (HTTP/1.1 400) 5 headers in 186 bytes (1 switches on core 0)
Invalid HTTP_HOST header: '101.42.36.160'. You may need to add '101.42.36.160' to ALLOWED_HOSTS.
Traceback (most recent call last):
  File "/home/ubuntu/.local/lib/python3.10/site-packages/django/core/handlers/exception.py", line 55, in inner
    response = get_response(request)
  File "/home/ubuntu/.local/lib/python3.10/site-packages/django/utils/deprecation.py", line 133, in __call__
    response = self.process_request(request)
  File "/home/ubuntu/.local/lib/python3.10/site-packages/django/middleware/common.py", line 48, in process_request
    host = request.get_host()
  File "/home/ubuntu/.local/lib/python3.10/site-packages/django/http/request.py", line 151, in get_host
    raise DisallowedHost(msg)
django.core.exceptions.DisallowedHost: Invalid HTTP_HOST header: '101.42.36.160'. You may need to add '101.42.36.160' to ALLOWED_HOSTS.
Bad Request: /api/treatments/list/
[pid: 76761|app: 0|req: 2/8] 219.239.227.188 () {40 vars in 770 bytes} [Fri May 24 17:13:51 2024] GET /api/treatments/list/ => generated 58702 bytes in 25 msecs (HTTP/1.1 400) 5 headers in 186 bytes (1 switches on core 1)
Invalid HTTP_HOST header: '101.42.36.160'. You may need to add '101.42.36.160' to ALLOWED_HOSTS.
Traceback (most recent call last):
  File "/home/ubuntu/.local/lib/python3.10/site-packages/django/core/handlers/exception.py", line 55, in inner
    response = get_response(request)
  File "/home/ubuntu/.local/lib/python3.10/site-packages/django/utils/deprecation.py", line 133, in __call__
    response = self.process_request(request)
  File "/home/ubuntu/.local/lib/python3.10/site-packages/django/middleware/common.py", line 48, in process_request
    host = request.get_host()
  File "/home/ubuntu/.local/lib/python3.10/site-packages/django/http/request.py", line 151, in get_host
    raise DisallowedHost(msg)
django.core.exceptions.DisallowedHost: Invalid HTTP_HOST header: '101.42.36.160'. You may need to add '101.42.36.160' to ALLOWED_HOSTS.
Bad Request: /api/treatments/list/
[pid: 76757|app: 0|req: 1/9] 219.239.227.188 () {40 vars in 770 bytes} [Fri May 24 17:13:52 2024] GET /api/treatments/list/ => generated 58702 bytes in 75 msecs (HTTP/1.1 400) 5 headers in 186 bytes (1 switches on core 0)
Invalid HTTP_HOST header: '101.42.36.160'. You may need to add '101.42.36.160' to ALLOWED_HOSTS.
Traceback (most recent call last):
  File "/home/ubuntu/.local/lib/python3.10/site-packages/django/core/handlers/exception.py", line 55, in inner
    response = get_response(request)
  File "/home/ubuntu/.local/lib/python3.10/site-packages/django/utils/deprecation.py", line 133, in __call__
    response = self.process_request(request)
  File "/home/ubuntu/.local/lib/python3.10/site-packages/django/middleware/common.py", line 48, in process_request
    host = request.get_host()
  File "/home/ubuntu/.local/lib/python3.10/site-packages/django/http/request.py", line 151, in get_host
    raise DisallowedHost(msg)
django.core.exceptions.DisallowedHost: Invalid HTTP_HOST header: '101.42.36.160'. You may need to add '101.42.36.160' to ALLOWED_HOSTS.
Bad Request: /api/treatments/list/
[pid: 76760|app: 0|req: 5/10] 219.239.227.188 () {38 vars in 651 bytes} [Fri May 24 17:14:49 2024] GET /api/treatments/list/ => generated 58477 bytes in 19 msecs (HTTP/1.1 400) 5 headers in 186 bytes (1 switches on core 0)
Invalid HTTP_HOST header: '101.42.36.160'. You may need to add '101.42.36.160' to ALLOWED_HOSTS.
Traceback (most recent call last):
  File "/home/ubuntu/.local/lib/python3.10/site-packages/django/core/handlers/exception.py", line 55, in inner
    response = get_response(request)
  File "/home/ubuntu/.local/lib/python3.10/site-packages/django/utils/deprecation.py", line 133, in __call__
    response = self.process_request(request)
  File "/home/ubuntu/.local/lib/python3.10/site-packages/django/middleware/common.py", line 48, in process_request
    host = request.get_host()
  File "/home/ubuntu/.local/lib/python3.10/site-packages/django/http/request.py", line 151, in get_host
    raise DisallowedHost(msg)
django.core.exceptions.DisallowedHost: Invalid HTTP_HOST header: '101.42.36.160'. You may need to add '101.42.36.160' to ALLOWED_HOSTS.
Bad Request: /api/treatments/list/
[pid: 76760|app: 0|req: 6/11] 219.239.227.188 () {38 vars in 739 bytes} [Fri May 24 17:14:59 2024] GET /api/treatments/list/ => generated 58565 bytes in 20 msecs (HTTP/1.1 400) 5 headers in 186 bytes (1 switches on core 1)
Invalid HTTP_HOST header: '101.42.36.160'. You may need to add '101.42.36.160' to ALLOWED_HOSTS.
Traceback (most recent call last):
  File "/home/ubuntu/.local/lib/python3.10/site-packages/django/core/handlers/exception.py", line 55, in inner
    response = get_response(request)
  File "/home/ubuntu/.local/lib/python3.10/site-packages/django/utils/deprecation.py", line 133, in __call__
    response = self.process_request(request)
  File "/home/ubuntu/.local/lib/python3.10/site-packages/django/middleware/common.py", line 48, in process_request
    host = request.get_host()
  File "/home/ubuntu/.local/lib/python3.10/site-packages/django/http/request.py", line 151, in get_host
    raise DisallowedHost(msg)
django.core.exceptions.DisallowedHost: Invalid HTTP_HOST header: '101.42.36.160'. You may need to add '101.42.36.160' to ALLOWED_HOSTS.
Bad Request: /api/treatments/list/
[pid: 76761|app: 0|req: 3/12] 219.239.227.188 () {38 vars in 651 bytes} [Fri May 24 17:17:06 2024] GET /api/treatments/list/ => generated 58477 bytes in 20 msecs (HTTP/1.1 400) 5 headers in 186 bytes (1 switches on core 0)
Invalid HTTP_HOST header: '101.42.36.160'. You may need to add '101.42.36.160' to ALLOWED_HOSTS.
Traceback (most recent call last):
  File "/home/ubuntu/.local/lib/python3.10/site-packages/django/core/handlers/exception.py", line 55, in inner
    response = get_response(request)
  File "/home/ubuntu/.local/lib/python3.10/site-packages/django/utils/deprecation.py", line 133, in __call__
    response = self.process_request(request)
  File "/home/ubuntu/.local/lib/python3.10/site-packages/django/middleware/common.py", line 48, in process_request
    host = request.get_host()
  File "/home/ubuntu/.local/lib/python3.10/site-packages/django/http/request.py", line 151, in get_host
    raise DisallowedHost(msg)
django.core.exceptions.DisallowedHost: Invalid HTTP_HOST header: '101.42.36.160'. You may need to add '101.42.36.160' to ALLOWED_HOSTS.
Bad Request: /api/treatments/list/
[pid: 76761|app: 0|req: 4/13] 219.239.227.188 () {38 vars in 739 bytes} [Fri May 24 17:17:12 2024] GET /api/treatments/list/ => generated 58565 bytes in 19 msecs (HTTP/1.1 400) 5 headers in 186 bytes (1 switches on core 1)
Invalid HTTP_HOST header: '101.42.36.160'. You may need to add '101.42.36.160' to ALLOWED_HOSTS.
Traceback (most recent call last):
  File "/home/ubuntu/.local/lib/python3.10/site-packages/django/core/handlers/exception.py", line 55, in inner
    response = get_response(request)
  File "/home/ubuntu/.local/lib/python3.10/site-packages/django/utils/deprecation.py", line 133, in __call__
    response = self.process_request(request)
  File "/home/ubuntu/.local/lib/python3.10/site-packages/django/middleware/common.py", line 48, in process_request
    host = request.get_host()
  File "/home/ubuntu/.local/lib/python3.10/site-packages/django/http/request.py", line 151, in get_host
    raise DisallowedHost(msg)
django.core.exceptions.DisallowedHost: Invalid HTTP_HOST header: '101.42.36.160'. You may need to add '101.42.36.160' to ALLOWED_HOSTS.
Bad Request: /api/treatments/list/
[pid: 76760|app: 0|req: 7/14] 219.239.227.188 () {38 vars in 651 bytes} [Fri May 24 17:19:09 2024] GET /api/treatments/list/ => generated 58477 bytes in 19 msecs (HTTP/1.1 400) 5 headers in 186 bytes (1 switches on core 0)
Invalid HTTP_HOST header: '101.42.36.160'. You may need to add '101.42.36.160' to ALLOWED_HOSTS.
Traceback (most recent call last):
  File "/home/ubuntu/.local/lib/python3.10/site-packages/django/core/handlers/exception.py", line 55, in inner
    response = get_response(request)
  File "/home/ubuntu/.local/lib/python3.10/site-packages/django/utils/deprecation.py", line 133, in __call__
    response = self.process_request(request)
  File "/home/ubuntu/.local/lib/python3.10/site-packages/django/middleware/common.py", line 48, in process_request
    host = request.get_host()
  File "/home/ubuntu/.local/lib/python3.10/site-packages/django/http/request.py", line 151, in get_host
    raise DisallowedHost(msg)
django.core.exceptions.DisallowedHost: Invalid HTTP_HOST header: '101.42.36.160'. You may need to add '101.42.36.160' to ALLOWED_HOSTS.
Bad Request: /api/treatments/list/
[pid: 76761|app: 0|req: 5/15] 219.239.227.188 () {38 vars in 651 bytes} [Fri May 24 17:19:26 2024] GET /api/treatments/list/ => generated 58477 bytes in 19 msecs (HTTP/1.1 400) 5 headers in 186 bytes (1 switches on core 0)
Invalid HTTP_HOST header: '101.42.36.160'. You may need to add '101.42.36.160' to ALLOWED_HOSTS.
Traceback (most recent call last):
  File "/home/ubuntu/.local/lib/python3.10/site-packages/django/core/handlers/exception.py", line 55, in inner
    response = get_response(request)
  File "/home/ubuntu/.local/lib/python3.10/site-packages/django/utils/deprecation.py", line 133, in __call__
    response = self.process_request(request)
  File "/home/ubuntu/.local/lib/python3.10/site-packages/django/middleware/common.py", line 48, in process_request
    host = request.get_host()
  File "/home/ubuntu/.local/lib/python3.10/site-packages/django/http/request.py", line 151, in get_host
    raise DisallowedHost(msg)
django.core.exceptions.DisallowedHost: Invalid HTTP_HOST header: '101.42.36.160'. You may need to add '101.42.36.160' to ALLOWED_HOSTS.
Bad Request: /api/treatments/list/
[pid: 76761|app: 0|req: 6/16] 219.239.227.188 () {38 vars in 739 bytes} [Fri May 24 17:19:33 2024] GET /api/treatments/list/ => generated 58565 bytes in 20 msecs (HTTP/1.1 400) 5 headers in 186 bytes (1 switches on core 1)
Invalid HTTP_HOST header: '101.42.36.160'. You may need to add '101.42.36.160' to ALLOWED_HOSTS.
Traceback (most recent call last):
  File "/home/ubuntu/.local/lib/python3.10/site-packages/django/core/handlers/exception.py", line 55, in inner
    response = get_response(request)
  File "/home/ubuntu/.local/lib/python3.10/site-packages/django/utils/deprecation.py", line 133, in __call__
    response = self.process_request(request)
  File "/home/ubuntu/.local/lib/python3.10/site-packages/django/middleware/common.py", line 48, in process_request
    host = request.get_host()
  File "/home/ubuntu/.local/lib/python3.10/site-packages/django/http/request.py", line 151, in get_host
    raise DisallowedHost(msg)
django.core.exceptions.DisallowedHost: Invalid HTTP_HOST header: '101.42.36.160'. You may need to add '101.42.36.160' to ALLOWED_HOSTS.
Bad Request: /api/treatments/list/
[pid: 76761|app: 0|req: 7/17] 219.239.227.188 () {38 vars in 651 bytes} [Fri May 24 17:21:07 2024] GET /api/treatments/list/ => generated 58477 bytes in 19 msecs (HTTP/1.1 400) 5 headers in 186 bytes (1 switches on core 0)
Invalid HTTP_HOST header: '101.42.36.160'. You may need to add '101.42.36.160' to ALLOWED_HOSTS.
Traceback (most recent call last):
  File "/home/ubuntu/.local/lib/python3.10/site-packages/django/core/handlers/exception.py", line 55, in inner
    response = get_response(request)
  File "/home/ubuntu/.local/lib/python3.10/site-packages/django/utils/deprecation.py", line 133, in __call__
    response = self.process_request(request)
  File "/home/ubuntu/.local/lib/python3.10/site-packages/django/middleware/common.py", line 48, in process_request
    host = request.get_host()
  File "/home/ubuntu/.local/lib/python3.10/site-packages/django/http/request.py", line 151, in get_host
    raise DisallowedHost(msg)
django.core.exceptions.DisallowedHost: Invalid HTTP_HOST header: '101.42.36.160'. You may need to add '101.42.36.160' to ALLOWED_HOSTS.
Bad Request: /api/treatments/list/
[pid: 76757|app: 0|req: 2/18] 219.239.227.188 () {38 vars in 651 bytes} [Fri May 24 17:22:54 2024] GET /api/treatments/list/ => generated 58477 bytes in 21 msecs (HTTP/1.1 400) 5 headers in 186 bytes (1 switches on core 1)
Invalid HTTP_HOST header: '101.42.36.160'. You may need to add '101.42.36.160' to ALLOWED_HOSTS.
Traceback (most recent call last):
  File "/home/ubuntu/.local/lib/python3.10/site-packages/django/core/handlers/exception.py", line 55, in inner
    response = get_response(request)
  File "/home/ubuntu/.local/lib/python3.10/site-packages/django/utils/deprecation.py", line 133, in __call__
    response = self.process_request(request)
  File "/home/ubuntu/.local/lib/python3.10/site-packages/django/middleware/common.py", line 48, in process_request
    host = request.get_host()
  File "/home/ubuntu/.local/lib/python3.10/site-packages/django/http/request.py", line 151, in get_host
    raise DisallowedHost(msg)
django.core.exceptions.DisallowedHost: Invalid HTTP_HOST header: '101.42.36.160'. You may need to add '101.42.36.160' to ALLOWED_HOSTS.
Bad Request: /api/treatments/list/
[pid: 76758|app: 0|req: 3/19] 219.239.227.188 () {38 vars in 739 bytes} [Fri May 24 17:22:58 2024] GET /api/treatments/list/ => generated 58565 bytes in 20 msecs (HTTP/1.1 400) 5 headers in 186 bytes (1 switches on core 0)
*** Starting uWSGI 2.0.25.1 (64bit) on [Sun May 26 10:46:18 2024] ***
compiled with version: 11.2.0 on 24 May 2024 14:41:03
os: Linux-5.15.0-86-generic #96-Ubuntu SMP Wed Sep 20 08:23:49 UTC 2023
nodename: VM-8-9-ubuntu
machine: x86_64
clock source: unix
detected number of CPU cores: 2
current working directory: /home/ubuntu/SEGroup6/猫猫就诊/Project
writing pidfile to uwsgi.pid
detected binary path: /usr/local/bin/uwsgi
!!! no internal routing support, rebuild with pcre support !!!
uWSGI running as root, you can use --uid/--gid/--chroot options
*** WARNING: you are running uWSGI as root !!! (use the --uid flag) *** 
chdir() to /home/ubuntu/SEGroup6/猫猫就诊/Project
your processes number limit is 7402
your memory page size is 4096 bytes
detected max file descriptor number: 1024
lock engine: pthread robust mutexes
thunder lock: disabled (you can enable it with --thunder-lock)
uwsgi socket 0 bound to TCP address 127.0.0.1:5000 fd 3
uWSGI running as root, you can use --uid/--gid/--chroot options
*** WARNING: you are running uWSGI as root !!! (use the --uid flag) *** 
Python version: 3.10.12 (main, Jun 11 2023, 05:26:28) [GCC 11.4.0]
Python main interpreter initialized at 0x556cba659290
uWSGI running as root, you can use --uid/--gid/--chroot options
*** WARNING: you are running uWSGI as root !!! (use the --uid flag) *** 
python threads support enabled
your server socket listen backlog is limited to 100 connections
your mercy for graceful operations on workers is 60 seconds
mapped 1031270 bytes (1007 KB) for 8 cores
*** Operational MODE: preforking+threaded ***
Traceback (most recent call last):
  File "/home/ubuntu/SEGroup6/猫猫就诊/Project/backend/wsgi.py", line 12, in <module>
    from django.core.wsgi import get_wsgi_application
ModuleNotFoundError: No module named 'django'
unable to load app 0 (mountpoint='') (callable not found or import error)
*** no app loaded. going in full dynamic mode ***
uWSGI running as root, you can use --uid/--gid/--chroot options
*** WARNING: you are running uWSGI as root !!! (use the --uid flag) *** 
*** uWSGI is running in multiple interpreter mode ***
spawned uWSGI master process (pid: 5638)
spawned uWSGI worker 1 (pid: 5651, cores: 2)
spawned uWSGI worker 2 (pid: 5652, cores: 2)
spawned uWSGI worker 3 (pid: 5653, cores: 2)
spawned uWSGI worker 4 (pid: 5655, cores: 2)
--- no python application found, check your startup logs for errors ---
[pid: 5655|app: -1|req: -1/1] 219.239.227.188 () {38 vars in 647 bytes} [Sun May 26 10:47:02 2024] GET /api/medicine/list/ => generated 21 bytes in 0 msecs (HTTP/1.1 500) 2 headers in 83 bytes (0 switches on core 0)
--- no python application found, check your startup logs for errors ---
[pid: 5651|app: -1|req: -1/2] 219.239.227.188 () {38 vars in 651 bytes} [Sun May 26 10:47:02 2024] GET /api/treatments/list/ => generated 21 bytes in 0 msecs (HTTP/1.1 500) 2 headers in 83 bytes (0 switches on core 0)
*** Starting uWSGI 2.0.25.1 (64bit) on [Sun May 26 11:04:31 2024] ***
compiled with version: 11.2.0 on 24 May 2024 14:41:03
os: Linux-5.15.0-86-generic #96-Ubuntu SMP Wed Sep 20 08:23:49 UTC 2023
nodename: VM-8-9-ubuntu
machine: x86_64
clock source: unix
detected number of CPU cores: 2
current working directory: /home/ubuntu/SEGroup6/猫猫就诊/Project
writing pidfile to uwsgi.pid
detected binary path: /usr/local/bin/uwsgi
!!! no internal routing support, rebuild with pcre support !!!
chdir() to /home/ubuntu/SEGroup6/猫猫就诊/Project
your processes number limit is 7402
your memory page size is 4096 bytes
detected max file descriptor number: 1024
lock engine: pthread robust mutexes
thunder lock: disabled (you can enable it with --thunder-lock)
probably another instance of uWSGI is running on the same address (127.0.0.1:5000).
bind(): Address already in use [core/socket.c line 769]
--- no python application found, check your startup logs for errors ---
[pid: 5655|app: -1|req: -1/3] 219.239.227.188 () {38 vars in 647 bytes} [Sun May 26 11:04:54 2024] GET /api/medicine/list/ => generated 21 bytes in 0 msecs (HTTP/1.1 500) 2 headers in 83 bytes (0 switches on core 0)
--- no python application found, check your startup logs for errors ---
[pid: 5655|app: -1|req: -1/4] 219.239.227.188 () {38 vars in 651 bytes} [Sun May 26 11:04:54 2024] GET /api/treatments/list/ => generated 21 bytes in 0 msecs (HTTP/1.1 500) 2 headers in 83 bytes (0 switches on core 1)
--- no python application found, check your startup logs for errors ---
[pid: 5655|app: -1|req: -1/5] 219.239.227.188 () {38 vars in 647 bytes} [Sun May 26 11:10:25 2024] GET /api/medicine/list/ => generated 21 bytes in 0 msecs (HTTP/1.1 500) 2 headers in 83 bytes (0 switches on core 0)
--- no python application found, check your startup logs for errors ---
[pid: 5655|app: -1|req: -1/6] 219.239.227.188 () {38 vars in 651 bytes} [Sun May 26 11:10:25 2024] GET /api/treatments/list/ => generated 21 bytes in 0 msecs (HTTP/1.1 500) 2 headers in 83 bytes (0 switches on core 1)
*** Starting uWSGI 2.0.25.1 (64bit) on [Sun May 26 11:14:22 2024] ***
compiled with version: 11.2.0 on 24 May 2024 14:41:03
os: Linux-5.15.0-86-generic #96-Ubuntu SMP Wed Sep 20 08:23:49 UTC 2023
nodename: VM-8-9-ubuntu
machine: x86_64
clock source: unix
detected number of CPU cores: 2
current working directory: /home/ubuntu/SEGroup6/猫猫就诊/Project
writing pidfile to uwsgi.pid
detected binary path: /usr/local/bin/uwsgi
!!! no internal routing support, rebuild with pcre support !!!
uWSGI running as root, you can use --uid/--gid/--chroot options
*** WARNING: you are running uWSGI as root !!! (use the --uid flag) *** 
chdir() to /home/ubuntu/SEGroup6/猫猫就诊/Project
your processes number limit is 7402
your memory page size is 4096 bytes
detected max file descriptor number: 1024
lock engine: pthread robust mutexes
thunder lock: disabled (you can enable it with --thunder-lock)
probably another instance of uWSGI is running on the same address (127.0.0.1:5000).
bind(): Address already in use [core/socket.c line 769]
--- no python application found, check your startup logs for errors ---
[pid: 5655|app: -1|req: -1/7] 219.239.227.188 () {38 vars in 647 bytes} [Sun May 26 11:14:37 2024] GET /api/medicine/list/ => generated 21 bytes in 0 msecs (HTTP/1.1 500) 2 headers in 83 bytes (0 switches on core 0)
--- no python application found, check your startup logs for errors ---
[pid: 5655|app: -1|req: -1/8] 219.239.227.188 () {38 vars in 651 bytes} [Sun May 26 11:14:37 2024] GET /api/treatments/list/ => generated 21 bytes in 0 msecs (HTTP/1.1 500) 2 headers in 83 bytes (0 switches on core 1)
*** Starting uWSGI 2.0.25.1 (64bit) on [Sun May 26 11:28:52 2024] ***
compiled with version: 11.2.0 on 24 May 2024 14:41:03
os: Linux-5.15.0-86-generic #96-Ubuntu SMP Wed Sep 20 08:23:49 UTC 2023
nodename: VM-8-9-ubuntu
machine: x86_64
clock source: unix
detected number of CPU cores: 2
current working directory: /home/ubuntu/SEGroup6/猫猫就诊/Project
writing pidfile to uwsgi.pid
detected binary path: /usr/local/bin/uwsgi
!!! no internal routing support, rebuild with pcre support !!!
uWSGI running as root, you can use --uid/--gid/--chroot options
*** WARNING: you are running uWSGI as root !!! (use the --uid flag) *** 
chdir() to /home/ubuntu/SEGroup6/猫猫就诊/Project
your processes number limit is 7402
your memory page size is 4096 bytes
detected max file descriptor number: 1024
lock engine: pthread robust mutexes
thunder lock: disabled (you can enable it with --thunder-lock)
probably another instance of uWSGI is running on the same address (127.0.0.1:5000).
bind(): Address already in use [core/socket.c line 769]
--- no python application found, check your startup logs for errors ---
[pid: 5655|app: -1|req: -1/9] 219.239.227.188 () {38 vars in 647 bytes} [Sun May 26 11:29:08 2024] GET /api/medicine/list/ => generated 21 bytes in 0 msecs (HTTP/1.1 500) 2 headers in 83 bytes (0 switches on core 0)
--- no python application found, check your startup logs for errors ---
[pid: 5652|app: -1|req: -1/10] 219.239.227.188 () {38 vars in 651 bytes} [Sun May 26 11:29:08 2024] GET /api/treatments/list/ => generated 21 bytes in 0 msecs (HTTP/1.1 500) 2 headers in 83 bytes (0 switches on core 0)
--- no python application found, check your startup logs for errors ---
[pid: 5652|app: -1|req: -1/11] 219.239.227.188 () {38 vars in 647 bytes} [Sun May 26 11:40:01 2024] GET /api/medicine/list/ => generated 21 bytes in 0 msecs (HTTP/1.1 500) 2 headers in 83 bytes (0 switches on core 1)
--- no python application found, check your startup logs for errors ---
[pid: 5653|app: -1|req: -1/12] 219.239.227.188 () {38 vars in 651 bytes} [Sun May 26 11:40:01 2024] GET /api/treatments/list/ => generated 21 bytes in 0 msecs (HTTP/1.1 500) 2 headers in 83 bytes (0 switches on core 0)
...brutally killing workers...
worker 1 buried after 1 seconds
worker 2 buried after 1 seconds
worker 3 buried after 1 seconds
worker 4 buried after 1 seconds
binary reloading uWSGI...
chdir() to /home/ubuntu/SEGroup6/猫猫就诊/Project
closing all non-uwsgi socket fds > 2 (max_fd = 1024)...
found fd 3 mapped to socket 0 (127.0.0.1:5000)
running /usr/local/bin/uwsgi
[uWSGI] getting INI configuration from uwsgi.ini
*** Starting uWSGI 2.0.25.1 (64bit) on [Sun May 26 11:42:43 2024] ***
compiled with version: 11.2.0 on 24 May 2024 14:41:03
os: Linux-5.15.0-86-generic #96-Ubuntu SMP Wed Sep 20 08:23:49 UTC 2023
nodename: VM-8-9-ubuntu
machine: x86_64
clock source: unix
detected number of CPU cores: 2
current working directory: /home/ubuntu/SEGroup6/猫猫就诊/Project
detected binary path: /usr/local/bin/uwsgi
!!! no internal routing support, rebuild with pcre support !!!
uWSGI running as root, you can use --uid/--gid/--chroot options
*** WARNING: you are running uWSGI as root !!! (use the --uid flag) *** 
chdir() to /home/ubuntu/SEGroup6/猫猫就诊/Project
your processes number limit is 7402
your memory page size is 4096 bytes
detected max file descriptor number: 1024
lock engine: pthread robust mutexes
thunder lock: disabled (you can enable it with --thunder-lock)
uwsgi socket 0 inherited INET address 127.0.0.1:5000 fd 3
uWSGI running as root, you can use --uid/--gid/--chroot options
*** WARNING: you are running uWSGI as root !!! (use the --uid flag) *** 
Python version: 3.10.12 (main, Jun 11 2023, 05:26:28) [GCC 11.4.0]
Python main interpreter initialized at 0x5654d830bcd0
uWSGI running as root, you can use --uid/--gid/--chroot options
*** WARNING: you are running uWSGI as root !!! (use the --uid flag) *** 
python threads support enabled
your server socket listen backlog is limited to 100 connections
your mercy for graceful operations on workers is 60 seconds
mapped 1031270 bytes (1007 KB) for 8 cores
*** Operational MODE: preforking+threaded ***
Traceback (most recent call last):
  File "/home/ubuntu/SEGroup6/猫猫就诊/Project/backend/wsgi.py", line 16, in <module>
    application = get_wsgi_application()
  File "/usr/local/lib/python3.10/dist-packages/django/core/wsgi.py", line 12, in get_wsgi_application
    django.setup(set_prefix=False)
  File "/usr/local/lib/python3.10/dist-packages/django/__init__.py", line 19, in setup
    configure_logging(settings.LOGGING_CONFIG, settings.LOGGING)
  File "/usr/local/lib/python3.10/dist-packages/django/conf/__init__.py", line 89, in __getattr__
    self._setup(name)
  File "/usr/local/lib/python3.10/dist-packages/django/conf/__init__.py", line 76, in _setup
    self._wrapped = Settings(settings_module)
  File "/usr/local/lib/python3.10/dist-packages/django/conf/__init__.py", line 190, in __init__
    mod = importlib.import_module(self.SETTINGS_MODULE)
  File "/usr/lib/python3.10/importlib/__init__.py", line 126, in import_module
    return _bootstrap._gcd_import(name[level:], package, level)
  File "<frozen importlib._bootstrap>", line 1050, in _gcd_import
  File "<frozen importlib._bootstrap>", line 1027, in _find_and_load
  File "<frozen importlib._bootstrap>", line 992, in _find_and_load_unlocked
  File "<frozen importlib._bootstrap>", line 241, in _call_with_frames_removed
  File "<frozen importlib._bootstrap>", line 1050, in _gcd_import
  File "<frozen importlib._bootstrap>", line 1027, in _find_and_load
  File "<frozen importlib._bootstrap>", line 1006, in _find_and_load_unlocked
  File "<frozen importlib._bootstrap>", line 688, in _load_unlocked
  File "<frozen importlib._bootstrap_external>", line 883, in exec_module
  File "<frozen importlib._bootstrap>", line 241, in _call_with_frames_removed
  File "/home/ubuntu/SEGroup6/猫猫就诊/Project/./backend/__init__.py", line 1, in <module>
    import pymysql
ModuleNotFoundError: No module named 'pymysql'
unable to load app 0 (mountpoint='') (callable not found or import error)
*** no app loaded. going in full dynamic mode ***
uWSGI running as root, you can use --uid/--gid/--chroot options
*** WARNING: you are running uWSGI as root !!! (use the --uid flag) *** 
*** uWSGI is running in multiple interpreter mode ***
gracefully (RE)spawned uWSGI master process (pid: 5638)
spawned uWSGI worker 1 (pid: 23599, cores: 2)
spawned uWSGI worker 2 (pid: 23600, cores: 2)
spawned uWSGI worker 3 (pid: 23602, cores: 2)
spawned uWSGI worker 4 (pid: 23603, cores: 2)
*** Starting uWSGI 2.0.25.1 (64bit) on [Sun May 26 11:42:48 2024] ***
compiled with version: 11.2.0 on 24 May 2024 14:41:03
os: Linux-5.15.0-86-generic #96-Ubuntu SMP Wed Sep 20 08:23:49 UTC 2023
nodename: VM-8-9-ubuntu
machine: x86_64
clock source: unix
detected number of CPU cores: 2
current working directory: /home/ubuntu/SEGroup6/猫猫就诊/Project
writing pidfile to uwsgi.pid
detected binary path: /usr/local/bin/uwsgi
!!! no internal routing support, rebuild with pcre support !!!
uWSGI running as root, you can use --uid/--gid/--chroot options
*** WARNING: you are running uWSGI as root !!! (use the --uid flag) *** 
chdir() to /home/ubuntu/SEGroup6/猫猫就诊/Project
your processes number limit is 7402
your memory page size is 4096 bytes
detected max file descriptor number: 1024
lock engine: pthread robust mutexes
thunder lock: disabled (you can enable it with --thunder-lock)
probably another instance of uWSGI is running on the same address (127.0.0.1:5000).
bind(): Address already in use [core/socket.c line 769]
--- no python application found, check your startup logs for errors ---
[pid: 23600|app: -1|req: -1/1] 219.239.227.188 () {38 vars in 647 bytes} [Sun May 26 11:43:07 2024] GET /api/medicine/list/ => generated 21 bytes in 0 msecs (HTTP/1.1 500) 2 headers in 83 bytes (0 switches on core 0)
--- no python application found, check your startup logs for errors ---
[pid: 23599|app: -1|req: -1/2] 219.239.227.188 () {38 vars in 651 bytes} [Sun May 26 11:43:07 2024] GET /api/treatments/list/ => generated 21 bytes in 0 msecs (HTTP/1.1 500) 2 headers in 83 bytes (0 switches on core 0)
...brutally killing workers...
worker 1 buried after 1 seconds
worker 2 buried after 1 seconds
worker 3 buried after 1 seconds
worker 4 buried after 1 seconds
binary reloading uWSGI...
chdir() to /home/ubuntu/SEGroup6/猫猫就诊/Project
closing all non-uwsgi socket fds > 2 (max_fd = 1024)...
found fd 3 mapped to socket 0 (127.0.0.1:5000)
running /usr/local/bin/uwsgi
[uWSGI] getting INI configuration from uwsgi.ini
*** Starting uWSGI 2.0.25.1 (64bit) on [Sun May 26 11:45:06 2024] ***
compiled with version: 11.2.0 on 24 May 2024 14:41:03
os: Linux-5.15.0-86-generic #96-Ubuntu SMP Wed Sep 20 08:23:49 UTC 2023
nodename: VM-8-9-ubuntu
machine: x86_64
clock source: unix
detected number of CPU cores: 2
current working directory: /home/ubuntu/SEGroup6/猫猫就诊/Project
detected binary path: /usr/local/bin/uwsgi
!!! no internal routing support, rebuild with pcre support !!!
uWSGI running as root, you can use --uid/--gid/--chroot options
*** WARNING: you are running uWSGI as root !!! (use the --uid flag) *** 
chdir() to /home/ubuntu/SEGroup6/猫猫就诊/Project
your processes number limit is 7402
your memory page size is 4096 bytes
detected max file descriptor number: 1024
lock engine: pthread robust mutexes
thunder lock: disabled (you can enable it with --thunder-lock)
uwsgi socket 0 inherited INET address 127.0.0.1:5000 fd 3
uWSGI running as root, you can use --uid/--gid/--chroot options
*** WARNING: you are running uWSGI as root !!! (use the --uid flag) *** 
Python version: 3.10.12 (main, Jun 11 2023, 05:26:28) [GCC 11.4.0]
Python main interpreter initialized at 0x560f371cdd00
uWSGI running as root, you can use --uid/--gid/--chroot options
*** WARNING: you are running uWSGI as root !!! (use the --uid flag) *** 
python threads support enabled
your server socket listen backlog is limited to 100 connections
your mercy for graceful operations on workers is 60 seconds
mapped 1031270 bytes (1007 KB) for 8 cores
*** Operational MODE: preforking+threaded ***
Traceback (most recent call last):
  File "/home/ubuntu/SEGroup6/猫猫就诊/Project/backend/wsgi.py", line 16, in <module>
    application = get_wsgi_application()
  File "/usr/local/lib/python3.10/dist-packages/django/core/wsgi.py", line 12, in get_wsgi_application
    django.setup(set_prefix=False)
  File "/usr/local/lib/python3.10/dist-packages/django/__init__.py", line 19, in setup
    configure_logging(settings.LOGGING_CONFIG, settings.LOGGING)
  File "/usr/local/lib/python3.10/dist-packages/django/conf/__init__.py", line 89, in __getattr__
    self._setup(name)
  File "/usr/local/lib/python3.10/dist-packages/django/conf/__init__.py", line 76, in _setup
    self._wrapped = Settings(settings_module)
  File "/usr/local/lib/python3.10/dist-packages/django/conf/__init__.py", line 190, in __init__
    mod = importlib.import_module(self.SETTINGS_MODULE)
  File "/usr/lib/python3.10/importlib/__init__.py", line 126, in import_module
    return _bootstrap._gcd_import(name[level:], package, level)
  File "<frozen importlib._bootstrap>", line 1050, in _gcd_import
  File "<frozen importlib._bootstrap>", line 1027, in _find_and_load
  File "<frozen importlib._bootstrap>", line 992, in _find_and_load_unlocked
  File "<frozen importlib._bootstrap>", line 241, in _call_with_frames_removed
  File "<frozen importlib._bootstrap>", line 1050, in _gcd_import
  File "<frozen importlib._bootstrap>", line 1027, in _find_and_load
  File "<frozen importlib._bootstrap>", line 1006, in _find_and_load_unlocked
  File "<frozen importlib._bootstrap>", line 688, in _load_unlocked
  File "<frozen importlib._bootstrap_external>", line 883, in exec_module
  File "<frozen importlib._bootstrap>", line 241, in _call_with_frames_removed
  File "/home/ubuntu/SEGroup6/猫猫就诊/Project/./backend/__init__.py", line 1, in <module>
    import pymysql
ModuleNotFoundError: No module named 'pymysql'
unable to load app 0 (mountpoint='') (callable not found or import error)
*** no app loaded. going in full dynamic mode ***
uWSGI running as root, you can use --uid/--gid/--chroot options
*** WARNING: you are running uWSGI as root !!! (use the --uid flag) *** 
*** uWSGI is running in multiple interpreter mode ***
gracefully (RE)spawned uWSGI master process (pid: 5638)
spawned uWSGI worker 1 (pid: 24364, cores: 2)
spawned uWSGI worker 2 (pid: 24365, cores: 2)
spawned uWSGI worker 3 (pid: 24367, cores: 2)
spawned uWSGI worker 4 (pid: 24368, cores: 2)
...brutally killing workers...
worker 1 buried after 1 seconds
worker 2 buried after 1 seconds
worker 3 buried after 1 seconds
worker 4 buried after 1 seconds
binary reloading uWSGI...
chdir() to /home/ubuntu/SEGroup6/猫猫就诊/Project
closing all non-uwsgi socket fds > 2 (max_fd = 1024)...
found fd 3 mapped to socket 0 (127.0.0.1:5000)
running /usr/local/bin/uwsgi
[uWSGI] getting INI configuration from uwsgi.ini
*** Starting uWSGI 2.0.25.1 (64bit) on [Sun May 26 11:45:38 2024] ***
compiled with version: 11.2.0 on 24 May 2024 14:41:03
os: Linux-5.15.0-86-generic #96-Ubuntu SMP Wed Sep 20 08:23:49 UTC 2023
nodename: VM-8-9-ubuntu
machine: x86_64
clock source: unix
detected number of CPU cores: 2
current working directory: /home/ubuntu/SEGroup6/猫猫就诊/Project
detected binary path: /usr/local/bin/uwsgi
!!! no internal routing support, rebuild with pcre support !!!
uWSGI running as root, you can use --uid/--gid/--chroot options
*** WARNING: you are running uWSGI as root !!! (use the --uid flag) *** 
chdir() to /home/ubuntu/SEGroup6/猫猫就诊/Project
your processes number limit is 7402
your memory page size is 4096 bytes
detected max file descriptor number: 1024
lock engine: pthread robust mutexes
thunder lock: disabled (you can enable it with --thunder-lock)
uwsgi socket 0 inherited INET address 127.0.0.1:5000 fd 3
uWSGI running as root, you can use --uid/--gid/--chroot options
*** WARNING: you are running uWSGI as root !!! (use the --uid flag) *** 
Python version: 3.10.12 (main, Jun 11 2023, 05:26:28) [GCC 11.4.0]
Python main interpreter initialized at 0x558d35df6d00
uWSGI running as root, you can use --uid/--gid/--chroot options
*** WARNING: you are running uWSGI as root !!! (use the --uid flag) *** 
python threads support enabled
your server socket listen backlog is limited to 100 connections
your mercy for graceful operations on workers is 60 seconds
mapped 1031270 bytes (1007 KB) for 8 cores
*** Operational MODE: preforking+threaded ***
Traceback (most recent call last):
  File "/home/ubuntu/SEGroup6/猫猫就诊/Project/backend/wsgi.py", line 16, in <module>
    application = get_wsgi_application()
  File "/usr/local/lib/python3.10/dist-packages/django/core/wsgi.py", line 12, in get_wsgi_application
    django.setup(set_prefix=False)
  File "/usr/local/lib/python3.10/dist-packages/django/__init__.py", line 19, in setup
    configure_logging(settings.LOGGING_CONFIG, settings.LOGGING)
  File "/usr/local/lib/python3.10/dist-packages/django/conf/__init__.py", line 89, in __getattr__
    self._setup(name)
  File "/usr/local/lib/python3.10/dist-packages/django/conf/__init__.py", line 76, in _setup
    self._wrapped = Settings(settings_module)
  File "/usr/local/lib/python3.10/dist-packages/django/conf/__init__.py", line 190, in __init__
    mod = importlib.import_module(self.SETTINGS_MODULE)
  File "/usr/lib/python3.10/importlib/__init__.py", line 126, in import_module
    return _bootstrap._gcd_import(name[level:], package, level)
  File "<frozen importlib._bootstrap>", line 1050, in _gcd_import
  File "<frozen importlib._bootstrap>", line 1027, in _find_and_load
  File "<frozen importlib._bootstrap>", line 992, in _find_and_load_unlocked
  File "<frozen importlib._bootstrap>", line 241, in _call_with_frames_removed
  File "<frozen importlib._bootstrap>", line 1050, in _gcd_import
  File "<frozen importlib._bootstrap>", line 1027, in _find_and_load
  File "<frozen importlib._bootstrap>", line 1006, in _find_and_load_unlocked
  File "<frozen importlib._bootstrap>", line 688, in _load_unlocked
  File "<frozen importlib._bootstrap_external>", line 883, in exec_module
  File "<frozen importlib._bootstrap>", line 241, in _call_with_frames_removed
  File "/home/ubuntu/SEGroup6/猫猫就诊/Project/./backend/__init__.py", line 1, in <module>
    import pymysql
ModuleNotFoundError: No module named 'pymysql'
unable to load app 0 (mountpoint='') (callable not found or import error)
*** no app loaded. going in full dynamic mode ***
uWSGI running as root, you can use --uid/--gid/--chroot options
*** WARNING: you are running uWSGI as root !!! (use the --uid flag) *** 
*** uWSGI is running in multiple interpreter mode ***
gracefully (RE)spawned uWSGI master process (pid: 5638)
spawned uWSGI worker 1 (pid: 24555, cores: 2)
spawned uWSGI worker 2 (pid: 24556, cores: 2)
spawned uWSGI worker 3 (pid: 24558, cores: 2)
spawned uWSGI worker 4 (pid: 24559, cores: 2)
...brutally killing workers...
worker 1 buried after 1 seconds
worker 2 buried after 1 seconds
worker 3 buried after 1 seconds
worker 4 buried after 1 seconds
binary reloading uWSGI...
chdir() to /home/ubuntu/SEGroup6/猫猫就诊/Project
closing all non-uwsgi socket fds > 2 (max_fd = 1024)...
found fd 3 mapped to socket 0 (127.0.0.1:5000)
running /usr/local/bin/uwsgi
[uWSGI] getting INI configuration from uwsgi.ini
*** Starting uWSGI 2.0.25.1 (64bit) on [Sun May 26 11:46:12 2024] ***
compiled with version: 11.2.0 on 24 May 2024 14:41:03
os: Linux-5.15.0-86-generic #96-Ubuntu SMP Wed Sep 20 08:23:49 UTC 2023
nodename: VM-8-9-ubuntu
machine: x86_64
clock source: unix
detected number of CPU cores: 2
current working directory: /home/ubuntu/SEGroup6/猫猫就诊/Project
detected binary path: /usr/local/bin/uwsgi
!!! no internal routing support, rebuild with pcre support !!!
uWSGI running as root, you can use --uid/--gid/--chroot options
*** WARNING: you are running uWSGI as root !!! (use the --uid flag) *** 
chdir() to /home/ubuntu/SEGroup6/猫猫就诊/Project
your processes number limit is 7402
your memory page size is 4096 bytes
detected max file descriptor number: 1024
lock engine: pthread robust mutexes
thunder lock: disabled (you can enable it with --thunder-lock)
uwsgi socket 0 inherited INET address 127.0.0.1:5000 fd 3
uWSGI running as root, you can use --uid/--gid/--chroot options
*** WARNING: you are running uWSGI as root !!! (use the --uid flag) *** 
Python version: 3.10.12 (main, Jun 11 2023, 05:26:28) [GCC 11.4.0]
Python main interpreter initialized at 0x55f37ee1dd00
uWSGI running as root, you can use --uid/--gid/--chroot options
*** WARNING: you are running uWSGI as root !!! (use the --uid flag) *** 
python threads support enabled
your server socket listen backlog is limited to 100 connections
your mercy for graceful operations on workers is 60 seconds
mapped 1031270 bytes (1007 KB) for 8 cores
*** Operational MODE: preforking+threaded ***
Traceback (most recent call last):
  File "/home/ubuntu/SEGroup6/猫猫就诊/Project/backend/wsgi.py", line 16, in <module>
    application = get_wsgi_application()
  File "/usr/local/lib/python3.10/dist-packages/django/core/wsgi.py", line 12, in get_wsgi_application
    django.setup(set_prefix=False)
  File "/usr/local/lib/python3.10/dist-packages/django/__init__.py", line 19, in setup
    configure_logging(settings.LOGGING_CONFIG, settings.LOGGING)
  File "/usr/local/lib/python3.10/dist-packages/django/conf/__init__.py", line 89, in __getattr__
    self._setup(name)
  File "/usr/local/lib/python3.10/dist-packages/django/conf/__init__.py", line 76, in _setup
    self._wrapped = Settings(settings_module)
  File "/usr/local/lib/python3.10/dist-packages/django/conf/__init__.py", line 190, in __init__
    mod = importlib.import_module(self.SETTINGS_MODULE)
  File "/usr/lib/python3.10/importlib/__init__.py", line 126, in import_module
    return _bootstrap._gcd_import(name[level:], package, level)
  File "<frozen importlib._bootstrap>", line 1050, in _gcd_import
  File "<frozen importlib._bootstrap>", line 1027, in _find_and_load
  File "<frozen importlib._bootstrap>", line 992, in _find_and_load_unlocked
  File "<frozen importlib._bootstrap>", line 241, in _call_with_frames_removed
  File "<frozen importlib._bootstrap>", line 1050, in _gcd_import
  File "<frozen importlib._bootstrap>", line 1027, in _find_and_load
  File "<frozen importlib._bootstrap>", line 1006, in _find_and_load_unlocked
  File "<frozen importlib._bootstrap>", line 688, in _load_unlocked
  File "<frozen importlib._bootstrap_external>", line 883, in exec_module
  File "<frozen importlib._bootstrap>", line 241, in _call_with_frames_removed
  File "/home/ubuntu/SEGroup6/猫猫就诊/Project/./backend/__init__.py", line 1, in <module>
    import pymysql
ModuleNotFoundError: No module named 'pymysql'
unable to load app 0 (mountpoint='') (callable not found or import error)
*** no app loaded. going in full dynamic mode ***
uWSGI running as root, you can use --uid/--gid/--chroot options
*** WARNING: you are running uWSGI as root !!! (use the --uid flag) *** 
*** uWSGI is running in multiple interpreter mode ***
gracefully (RE)spawned uWSGI master process (pid: 5638)
spawned uWSGI worker 1 (pid: 24742, cores: 2)
spawned uWSGI worker 2 (pid: 24743, cores: 2)
spawned uWSGI worker 3 (pid: 24745, cores: 2)
spawned uWSGI worker 4 (pid: 24746, cores: 2)
Sun May 26 11:46:32 2024 - uWSGI worker 3 screams: UAAAAAAH my master disconnected: i will kill myself !!!
Sun May 26 11:46:32 2024 - uWSGI worker 4 screams: UAAAAAAH my master disconnected: i will kill myself !!!
Sun May 26 11:46:32 2024 - uWSGI worker 3 screams: UAAAAAAH my master disconnected: i will kill myself !!!
Sun May 26 11:46:32 2024 - uWSGI worker 2 screams: UAAAAAAH my master disconnected: i will kill myself !!!
Sun May 26 11:46:32 2024 - uWSGI worker 2 screams: UAAAAAAH my master disconnected: i will kill myself !!!
Sun May 26 11:46:32 2024 - uWSGI worker 1 screams: UAAAAAAH my master disconnected: i will kill myself !!!
Sun May 26 11:46:32 2024 - uWSGI worker 4 screams: UAAAAAAH my master disconnected: i will kill myself !!!
Sun May 26 11:46:32 2024 - uWSGI worker 1 screams: UAAAAAAH my master disconnected: i will kill myself !!!
*** Starting uWSGI 2.0.25.1 (64bit) on [Sun May 26 11:47:21 2024] ***
compiled with version: 11.2.0 on 24 May 2024 14:41:03
os: Linux-5.15.0-86-generic #96-Ubuntu SMP Wed Sep 20 08:23:49 UTC 2023
nodename: VM-8-9-ubuntu
machine: x86_64
clock source: unix
detected number of CPU cores: 2
current working directory: /home/ubuntu/SEGroup6/猫猫就诊/Project
writing pidfile to uwsgi.pid
detected binary path: /usr/local/bin/uwsgi
!!! no internal routing support, rebuild with pcre support !!!
uWSGI running as root, you can use --uid/--gid/--chroot options
*** WARNING: you are running uWSGI as root !!! (use the --uid flag) *** 
chdir() to /home/ubuntu/SEGroup6/猫猫就诊/Project
your processes number limit is 7402
your memory page size is 4096 bytes
detected max file descriptor number: 1024
lock engine: pthread robust mutexes
thunder lock: disabled (you can enable it with --thunder-lock)
uwsgi socket 0 bound to TCP address 127.0.0.1:5000 fd 3
uWSGI running as root, you can use --uid/--gid/--chroot options
*** WARNING: you are running uWSGI as root !!! (use the --uid flag) *** 
Python version: 3.10.12 (main, Jun 11 2023, 05:26:28) [GCC 11.4.0]
Python main interpreter initialized at 0x55f3141c6290
uWSGI running as root, you can use --uid/--gid/--chroot options
*** WARNING: you are running uWSGI as root !!! (use the --uid flag) *** 
python threads support enabled
your server socket listen backlog is limited to 100 connections
your mercy for graceful operations on workers is 60 seconds
mapped 1031270 bytes (1007 KB) for 8 cores
*** Operational MODE: preforking+threaded ***
Traceback (most recent call last):
  File "/home/ubuntu/SEGroup6/猫猫就诊/Project/backend/wsgi.py", line 16, in <module>
    application = get_wsgi_application()
  File "/usr/local/lib/python3.10/dist-packages/django/core/wsgi.py", line 12, in get_wsgi_application
    django.setup(set_prefix=False)
  File "/usr/local/lib/python3.10/dist-packages/django/__init__.py", line 19, in setup
    configure_logging(settings.LOGGING_CONFIG, settings.LOGGING)
  File "/usr/local/lib/python3.10/dist-packages/django/conf/__init__.py", line 89, in __getattr__
    self._setup(name)
  File "/usr/local/lib/python3.10/dist-packages/django/conf/__init__.py", line 76, in _setup
    self._wrapped = Settings(settings_module)
  File "/usr/local/lib/python3.10/dist-packages/django/conf/__init__.py", line 190, in __init__
    mod = importlib.import_module(self.SETTINGS_MODULE)
  File "/usr/lib/python3.10/importlib/__init__.py", line 126, in import_module
    return _bootstrap._gcd_import(name[level:], package, level)
  File "<frozen importlib._bootstrap>", line 1050, in _gcd_import
  File "<frozen importlib._bootstrap>", line 1027, in _find_and_load
  File "<frozen importlib._bootstrap>", line 992, in _find_and_load_unlocked
  File "<frozen importlib._bootstrap>", line 241, in _call_with_frames_removed
  File "<frozen importlib._bootstrap>", line 1050, in _gcd_import
  File "<frozen importlib._bootstrap>", line 1027, in _find_and_load
  File "<frozen importlib._bootstrap>", line 1006, in _find_and_load_unlocked
  File "<frozen importlib._bootstrap>", line 688, in _load_unlocked
  File "<frozen importlib._bootstrap_external>", line 883, in exec_module
  File "<frozen importlib._bootstrap>", line 241, in _call_with_frames_removed
  File "/home/ubuntu/SEGroup6/猫猫就诊/Project/./backend/__init__.py", line 1, in <module>
    import pymysql
ModuleNotFoundError: No module named 'pymysql'
unable to load app 0 (mountpoint='') (callable not found or import error)
*** no app loaded. going in full dynamic mode ***
uWSGI running as root, you can use --uid/--gid/--chroot options
*** WARNING: you are running uWSGI as root !!! (use the --uid flag) *** 
*** uWSGI is running in multiple interpreter mode ***
spawned uWSGI master process (pid: 25140)
spawned uWSGI worker 1 (pid: 25144, cores: 2)
spawned uWSGI worker 2 (pid: 25145, cores: 2)
spawned uWSGI worker 3 (pid: 25147, cores: 2)
spawned uWSGI worker 4 (pid: 25148, cores: 2)
--- no python application found, check your startup logs for errors ---
[pid: 25148|app: -1|req: -1/1] 219.239.227.188 () {38 vars in 647 bytes} [Sun May 26 11:47:36 2024] GET /api/medicine/list/ => generated 21 bytes in 0 msecs (HTTP/1.1 500) 2 headers in 83 bytes (0 switches on core 0)
--- no python application found, check your startup logs for errors ---
[pid: 25145|app: -1|req: -1/2] 219.239.227.188 () {38 vars in 651 bytes} [Sun May 26 11:47:36 2024] GET /api/treatments/list/ => generated 21 bytes in 0 msecs (HTTP/1.1 500) 2 headers in 83 bytes (0 switches on core 0)
--- no python application found, check your startup logs for errors ---
[pid: 25148|app: -1|req: -1/3] 219.239.227.188 () {38 vars in 647 bytes} [Sun May 26 11:47:54 2024] GET /api/medicine/list/ => generated 21 bytes in 0 msecs (HTTP/1.1 500) 2 headers in 83 bytes (0 switches on core 1)
--- no python application found, check your startup logs for errors ---
[pid: 25144|app: -1|req: -1/4] 219.239.227.188 () {38 vars in 651 bytes} [Sun May 26 11:47:54 2024] GET /api/treatments/list/ => generated 21 bytes in 0 msecs (HTTP/1.1 500) 2 headers in 83 bytes (0 switches on core 0)
...gracefully killing workers...
Gracefully killing worker 1 (pid: 25144)...
Gracefully killing worker 2 (pid: 25145)...
Gracefully killing worker 3 (pid: 25147)...
Gracefully killing worker 4 (pid: 25148)...
--- no python application found, check your startup logs for errors ---
[pid: 25145|app: -1|req: -1/5] 219.239.227.188 () {38 vars in 647 bytes} [Sun May 26 11:50:06 2024] GET /api/medicine/list/ => generated 21 bytes in 0 msecs (HTTP/1.1 500) 2 headers in 83 bytes (0 switches on core 1)
worker 1 buried after 7 seconds
worker 2 buried after 7 seconds
Sun May 26 11:51:01 2024 - worker 3 (pid: 25147) is taking too much time to die...NO MERCY !!!
Sun May 26 11:51:01 2024 - worker 4 (pid: 25148) is taking too much time to die...NO MERCY !!!
worker 3 buried after 1 seconds
worker 4 buried after 1 seconds
binary reloading uWSGI...
chdir() to /home/ubuntu/SEGroup6/猫猫就诊/Project
closing all non-uwsgi socket fds > 2 (max_fd = 1024)...
found fd 3 mapped to socket 0 (127.0.0.1:5000)
running /usr/local/bin/uwsgi
[uWSGI] getting INI configuration from uwsgi.ini
*** Starting uWSGI 2.0.25.1 (64bit) on [Sun May 26 11:51:02 2024] ***
compiled with version: 11.2.0 on 24 May 2024 14:41:03
os: Linux-5.15.0-86-generic #96-Ubuntu SMP Wed Sep 20 08:23:49 UTC 2023
nodename: VM-8-9-ubuntu
machine: x86_64
clock source: unix
detected number of CPU cores: 2
current working directory: /home/ubuntu/SEGroup6/猫猫就诊/Project
detected binary path: /usr/local/bin/uwsgi
!!! no internal routing support, rebuild with pcre support !!!
uWSGI running as root, you can use --uid/--gid/--chroot options
*** WARNING: you are running uWSGI as root !!! (use the --uid flag) *** 
chdir() to /home/ubuntu/SEGroup6/猫猫就诊/Project
your processes number limit is 7402
your memory page size is 4096 bytes
detected max file descriptor number: 1024
lock engine: pthread robust mutexes
thunder lock: disabled (you can enable it with --thunder-lock)
uwsgi socket 0 inherited INET address 127.0.0.1:5000 fd 3
uWSGI running as root, you can use --uid/--gid/--chroot options
*** WARNING: you are running uWSGI as root !!! (use the --uid flag) *** 
Python version: 3.10.12 (main, Jun 11 2023, 05:26:28) [GCC 11.4.0]
Python main interpreter initialized at 0x5601f06d5d00
uWSGI running as root, you can use --uid/--gid/--chroot options
*** WARNING: you are running uWSGI as root !!! (use the --uid flag) *** 
python threads support enabled
your server socket listen backlog is limited to 100 connections
your mercy for graceful operations on workers is 60 seconds
mapped 1031270 bytes (1007 KB) for 8 cores
*** Operational MODE: preforking+threaded ***
Traceback (most recent call last):
  File "/home/ubuntu/SEGroup6/猫猫就诊/Project/backend/wsgi.py", line 16, in <module>
    application = get_wsgi_application()
  File "/usr/local/lib/python3.10/dist-packages/django/core/wsgi.py", line 12, in get_wsgi_application
    django.setup(set_prefix=False)
  File "/usr/local/lib/python3.10/dist-packages/django/__init__.py", line 24, in setup
    apps.populate(settings.INSTALLED_APPS)
  File "/usr/local/lib/python3.10/dist-packages/django/apps/registry.py", line 91, in populate
    app_config = AppConfig.create(entry)
  File "/usr/local/lib/python3.10/dist-packages/django/apps/config.py", line 193, in create
    import_module(entry)
  File "/usr/lib/python3.10/importlib/__init__.py", line 126, in import_module
    return _bootstrap._gcd_import(name[level:], package, level)
  File "<frozen importlib._bootstrap>", line 1050, in _gcd_import
  File "<frozen importlib._bootstrap>", line 1027, in _find_and_load
  File "<frozen importlib._bootstrap>", line 1004, in _find_and_load_unlocked
ModuleNotFoundError: No module named 'corsheaders'
unable to load app 0 (mountpoint='') (callable not found or import error)
*** no app loaded. going in full dynamic mode ***
uWSGI running as root, you can use --uid/--gid/--chroot options
*** WARNING: you are running uWSGI as root !!! (use the --uid flag) *** 
*** uWSGI is running in multiple interpreter mode ***
gracefully (RE)spawned uWSGI master process (pid: 25140)
spawned uWSGI worker 1 (pid: 26287, cores: 2)
spawned uWSGI worker 2 (pid: 26289, cores: 2)
--- no python application found, check your startup logs for errors ---
[pid: 26287|app: -1|req: -1/1] 219.239.227.188 () {38 vars in 651 bytes} [Sun May 26 03:51:02 2024] GET /api/treatments/list/ => generated 21 bytes in 0 msecs (HTTP/1.1 500) 2 headers in 83 bytes (0 switches on core 0)
spawned uWSGI worker 3 (pid: 26290, cores: 2)
spawned uWSGI worker 4 (pid: 26292, cores: 2)
--- no python application found, check your startup logs for errors ---
[pid: 26289|app: -1|req: -1/2] 219.239.227.188 () {38 vars in 647 bytes} [Sun May 26 03:51:50 2024] GET /api/medicine/list/ => generated 21 bytes in 0 msecs (HTTP/1.1 500) 2 headers in 83 bytes (0 switches on core 0)
--- no python application found, check your startup logs for errors ---
[pid: 26287|app: -1|req: -1/3] 219.239.227.188 () {38 vars in 651 bytes} [Sun May 26 03:51:50 2024] GET /api/treatments/list/ => generated 21 bytes in 0 msecs (HTTP/1.1 500) 2 headers in 83 bytes (0 switches on core 0)
...gracefully killing workers...
Gracefully killing worker 1 (pid: 26287)...
Gracefully killing worker 2 (pid: 26289)...
Gracefully killing worker 3 (pid: 26290)...
Gracefully killing worker 4 (pid: 26292)...
--- no python application found, check your startup logs for errors ---
--- no python application found, check your startup logs for errors ---
[pid: 26287|app: -1|req: -1/5] 219.239.227.188 () {38 vars in 651 bytes} [Sun May 26 03:54:39 2024] GET /api/treatments/list/ => generated 21 bytes in 0 msecs (HTTP/1.1 500) 2 headers in 83 bytes (0 switches on core 1)
[pid: 26289|app: -1|req: -1/5] 219.239.227.188 () {38 vars in 647 bytes} [Sun May 26 03:54:39 2024] GET /api/medicine/list/ => generated 21 bytes in 0 msecs (HTTP/1.1 500) 2 headers in 83 bytes (0 switches on core 1)
worker 1 buried after 13 seconds
worker 2 buried after 13 seconds
Sun May 26 03:55:27 2024 - worker 3 (pid: 26290) is taking too much time to die...NO MERCY !!!
Sun May 26 03:55:27 2024 - worker 4 (pid: 26292) is taking too much time to die...NO MERCY !!!
worker 3 buried after 0 seconds
worker 4 buried after 1 seconds
binary reloading uWSGI...
chdir() to /home/ubuntu/SEGroup6/猫猫就诊/Project
closing all non-uwsgi socket fds > 2 (max_fd = 1024)...
found fd 3 mapped to socket 0 (127.0.0.1:5000)
running /usr/local/bin/uwsgi
[uWSGI] getting INI configuration from uwsgi.ini
*** Starting uWSGI 2.0.25.1 (64bit) on [Sun May 26 03:55:28 2024] ***
compiled with version: 11.2.0 on 24 May 2024 14:41:03
os: Linux-5.15.0-86-generic #96-Ubuntu SMP Wed Sep 20 08:23:49 UTC 2023
nodename: VM-8-9-ubuntu
machine: x86_64
clock source: unix
detected number of CPU cores: 2
current working directory: /home/ubuntu/SEGroup6/猫猫就诊/Project
detected binary path: /usr/local/bin/uwsgi
!!! no internal routing support, rebuild with pcre support !!!
uWSGI running as root, you can use --uid/--gid/--chroot options
*** WARNING: you are running uWSGI as root !!! (use the --uid flag) *** 
chdir() to /home/ubuntu/SEGroup6/猫猫就诊/Project
your processes number limit is 7402
your memory page size is 4096 bytes
detected max file descriptor number: 1024
lock engine: pthread robust mutexes
thunder lock: disabled (you can enable it with --thunder-lock)
uwsgi socket 0 inherited INET address 127.0.0.1:5000 fd 3
uWSGI running as root, you can use --uid/--gid/--chroot options
*** WARNING: you are running uWSGI as root !!! (use the --uid flag) *** 
Python version: 3.10.12 (main, Jun 11 2023, 05:26:28) [GCC 11.4.0]
Python main interpreter initialized at 0x561fb81a2bd0
uWSGI running as root, you can use --uid/--gid/--chroot options
*** WARNING: you are running uWSGI as root !!! (use the --uid flag) *** 
python threads support enabled
your server socket listen backlog is limited to 100 connections
your mercy for graceful operations on workers is 60 seconds
mapped 1031270 bytes (1007 KB) for 8 cores
*** Operational MODE: preforking+threaded ***
WSGI app 0 (mountpoint='') ready in 0 seconds on interpreter 0x561fb81a2bd0 pid: 25140 (default app)
uWSGI running as root, you can use --uid/--gid/--chroot options
*** WARNING: you are running uWSGI as root !!! (use the --uid flag) *** 
*** uWSGI is running in multiple interpreter mode ***
gracefully (RE)spawned uWSGI master process (pid: 25140)
spawned uWSGI worker 1 (pid: 27679, cores: 2)
spawned uWSGI worker 2 (pid: 27680, cores: 2)
spawned uWSGI worker 3 (pid: 27682, cores: 2)
spawned uWSGI worker 4 (pid: 27683, cores: 2)
Sun May 26 03:57:41 2024 - uWSGI worker 2 screams: UAAAAAAH my master disconnected: i will kill myself !!!
Sun May 26 03:57:41 2024 - uWSGI worker 4 screams: UAAAAAAH my master disconnected: i will kill myself !!!
Sun May 26 03:57:41 2024 - uWSGI worker 1 screams: UAAAAAAH my master disconnected: i will kill myself !!!
Sun May 26 03:57:41 2024 - uWSGI worker 3 screams: UAAAAAAH my master disconnected: i will kill myself !!!
Sun May 26 03:57:41 2024 - uWSGI worker 2 screams: UAAAAAAH my master disconnected: i will kill myself !!!
Sun May 26 03:57:41 2024 - uWSGI worker 1 screams: UAAAAAAH my master disconnected: i will kill myself !!!
Sun May 26 03:57:41 2024 - uWSGI worker 4 screams: UAAAAAAH my master disconnected: i will kill myself !!!
Sun May 26 03:57:41 2024 - uWSGI worker 3 screams: UAAAAAAH my master disconnected: i will kill myself !!!
*** Starting uWSGI 2.0.25.1 (64bit) on [Sun May 26 11:58:18 2024] ***
compiled with version: 11.2.0 on 24 May 2024 14:41:03
os: Linux-5.15.0-86-generic #96-Ubuntu SMP Wed Sep 20 08:23:49 UTC 2023
nodename: VM-8-9-ubuntu
machine: x86_64
clock source: unix
detected number of CPU cores: 2
current working directory: /home/ubuntu/SEGroup6/猫猫就诊/Project
writing pidfile to uwsgi.pid
detected binary path: /usr/local/bin/uwsgi
!!! no internal routing support, rebuild with pcre support !!!
uWSGI running as root, you can use --uid/--gid/--chroot options
*** WARNING: you are running uWSGI as root !!! (use the --uid flag) *** 
chdir() to /home/ubuntu/SEGroup6/猫猫就诊/Project
your processes number limit is 7402
your memory page size is 4096 bytes
detected max file descriptor number: 1024
lock engine: pthread robust mutexes
thunder lock: disabled (you can enable it with --thunder-lock)
uwsgi socket 0 bound to TCP address 127.0.0.1:5000 fd 3
uWSGI running as root, you can use --uid/--gid/--chroot options
*** WARNING: you are running uWSGI as root !!! (use the --uid flag) *** 
Python version: 3.10.12 (main, Jun 11 2023, 05:26:28) [GCC 11.4.0]
Python main interpreter initialized at 0x55bf58851290
uWSGI running as root, you can use --uid/--gid/--chroot options
*** WARNING: you are running uWSGI as root !!! (use the --uid flag) *** 
python threads support enabled
your server socket listen backlog is limited to 100 connections
your mercy for graceful operations on workers is 60 seconds
mapped 1031270 bytes (1007 KB) for 8 cores
*** Operational MODE: preforking+threaded ***
WSGI app 0 (mountpoint='') ready in 0 seconds on interpreter 0x55bf58851290 pid: 28578 (default app)
uWSGI running as root, you can use --uid/--gid/--chroot options
*** WARNING: you are running uWSGI as root !!! (use the --uid flag) *** 
*** uWSGI is running in multiple interpreter mode ***
spawned uWSGI master process (pid: 28578)
spawned uWSGI worker 1 (pid: 28594, cores: 2)
spawned uWSGI worker 2 (pid: 28595, cores: 2)
spawned uWSGI worker 3 (pid: 28597, cores: 2)
spawned uWSGI worker 4 (pid: 28598, cores: 2)
Traceback (most recent call last):
  File "/usr/local/lib/python3.10/dist-packages/django/core/handlers/exception.py", line 55, in inner
    response = get_response(request)
  File "/usr/local/lib/python3.10/dist-packages/django/core/handlers/base.py", line 181, in _get_response
    callback, callback_args, callback_kwargs = self.resolve_request(request)
  File "/usr/local/lib/python3.10/dist-packages/django/core/handlers/base.py", line 313, in resolve_request
    resolver_match = resolver.resolve(request.path_info)
  File "/usr/local/lib/python3.10/dist-packages/django/urls/resolvers.py", line 686, in resolve
    for pattern in self.url_patterns:
  File "/usr/local/lib/python3.10/dist-packages/django/utils/functional.py", line 47, in __get__
    res = instance.__dict__[self.name] = self.func(instance)
  File "/usr/local/lib/python3.10/dist-packages/django/urls/resolvers.py", line 738, in url_patterns
    patterns = getattr(self.urlconf_module, "urlpatterns", self.urlconf_module)
  File "/usr/local/lib/python3.10/dist-packages/django/utils/functional.py", line 47, in __get__
    res = instance.__dict__[self.name] = self.func(instance)
  File "/usr/local/lib/python3.10/dist-packages/django/urls/resolvers.py", line 731, in urlconf_module
    return import_module(self.urlconf_name)
  File "/usr/lib/python3.10/importlib/__init__.py", line 126, in import_module
    return _bootstrap._gcd_import(name[level:], package, level)
  File "<frozen importlib._bootstrap>", line 1050, in _gcd_import
  File "<frozen importlib._bootstrap>", line 1027, in _find_and_load
  File "<frozen importlib._bootstrap>", line 1006, in _find_and_load_unlocked
  File "<frozen importlib._bootstrap>", line 688, in _load_unlocked
  File "<frozen importlib._bootstrap_external>", line 883, in exec_module
  File "<frozen importlib._bootstrap>", line 241, in _call_with_frames_removed
  File "/home/ubuntu/SEGroup6/猫猫就诊/Project/./backend/urls.py", line 19, in <module>
    from app01 import views
  File "/home/ubuntu/SEGroup6/猫猫就诊/Project/./app01/views.py", line 7, in <module>
    from rest_framework.views import APIView
ModuleNotFoundError: No module named 'rest_framework'

During handling of the above exception, another exception occurred:

Traceback (most recent call last):
  File "/usr/local/lib/python3.10/dist-packages/django/core/handlers/exception.py", line 55, in inner
    response = get_response(request)
  File "/usr/local/lib/python3.10/dist-packages/django/utils/deprecation.py", line 134, in __call__
    response = response or self.get_response(request)
  File "/usr/local/lib/python3.10/dist-packages/django/core/handlers/exception.py", line 57, in inner
    response = response_for_exception(request, exc)
  File "/usr/local/lib/python3.10/dist-packages/django/core/handlers/exception.py", line 140, in response_for_exception
    response = handle_uncaught_exception(
  File "/usr/local/lib/python3.10/dist-packages/django/core/handlers/exception.py", line 181, in handle_uncaught_exception
    return debug.technical_500_response(request, *exc_info)
  File "/usr/local/lib/python3.10/dist-packages/django/views/debug.py", line 69, in technical_500_response
    html = reporter.get_traceback_html()
  File "/usr/local/lib/python3.10/dist-packages/django/views/debug.py", line 428, in get_traceback_html
    c = Context(self.get_traceback_data(), use_l10n=False)
  File "/usr/local/lib/python3.10/dist-packages/django/views/debug.py", line 411, in get_traceback_data
    c["raising_view_name"] = get_caller(self.request)
  File "/usr/local/lib/python3.10/dist-packages/django/views/debug.py", line 102, in get_caller
    resolver_match = resolve(request.path)
  File "/usr/local/lib/python3.10/dist-packages/django/urls/base.py", line 24, in resolve
    return get_resolver(urlconf).resolve(path)
  File "/usr/local/lib/python3.10/dist-packages/django/urls/resolvers.py", line 686, in resolve
    for pattern in self.url_patterns:
  File "/usr/local/lib/python3.10/dist-packages/django/utils/functional.py", line 47, in __get__
    res = instance.__dict__[self.name] = self.func(instance)
  File "/usr/local/lib/python3.10/dist-packages/django/urls/resolvers.py", line 738, in url_patterns
    patterns = getattr(self.urlconf_module, "urlpatterns", self.urlconf_module)
  File "/usr/local/lib/python3.10/dist-packages/django/utils/functional.py", line 47, in __get__
    res = instance.__dict__[self.name] = self.func(instance)
  File "/usr/local/lib/python3.10/dist-packages/django/urls/resolvers.py", line 731, in urlconf_module
    return import_module(self.urlconf_name)
  File "/usr/lib/python3.10/importlib/__init__.py", line 126, in import_module
    return _bootstrap._gcd_import(name[level:], package, level)
  File "<frozen importlib._bootstrap>", line 1050, in _gcd_import
  File "<frozen importlib._bootstrap>", line 1027, in _find_and_load
  File "<frozen importlib._bootstrap>", line 1006, in _find_and_load_unlocked
  File "<frozen importlib._bootstrap>", line 688, in _load_unlocked
  File "<frozen importlib._bootstrap_external>", line 883, in exec_module
  File "<frozen importlib._bootstrap>", line 241, in _call_with_frames_removed
  File "/home/ubuntu/SEGroup6/猫猫就诊/Project/./backend/urls.py", line 19, in <module>
    from app01 import views
  File "/home/ubuntu/SEGroup6/猫猫就诊/Project/./app01/views.py", line 7, in <module>
    from rest_framework.views import APIView
ModuleNotFoundError: No module named 'rest_framework'

During handling of the above exception, another exception occurred:

Traceback (most recent call last):
  File "/usr/local/lib/python3.10/dist-packages/django/core/handlers/exception.py", line 55, in inner
    response = get_response(request)
  File "/usr/local/lib/python3.10/dist-packages/django/utils/deprecation.py", line 134, in __call__
    response = response or self.get_response(request)
  File "/usr/local/lib/python3.10/dist-packages/django/core/handlers/exception.py", line 57, in inner
    response = response_for_exception(request, exc)
  File "/usr/local/lib/python3.10/dist-packages/django/core/handlers/exception.py", line 140, in response_for_exception
    response = handle_uncaught_exception(
  File "/usr/local/lib/python3.10/dist-packages/django/core/handlers/exception.py", line 181, in handle_uncaught_exception
    return debug.technical_500_response(request, *exc_info)
  File "/usr/local/lib/python3.10/dist-packages/django/views/debug.py", line 69, in technical_500_response
    html = reporter.get_traceback_html()
  File "/usr/local/lib/python3.10/dist-packages/django/views/debug.py", line 428, in get_traceback_html
    c = Context(self.get_traceback_data(), use_l10n=False)
  File "/usr/local/lib/python3.10/dist-packages/django/views/debug.py", line 411, in get_traceback_data
    c["raising_view_name"] = get_caller(self.request)
  File "/usr/local/lib/python3.10/dist-packages/django/views/debug.py", line 102, in get_caller
    resolver_match = resolve(request.path)
  File "/usr/local/lib/python3.10/dist-packages/django/urls/base.py", line 24, in resolve
    return get_resolver(urlconf).resolve(path)
  File "/usr/local/lib/python3.10/dist-packages/django/urls/resolvers.py", line 686, in resolve
    for pattern in self.url_patterns:
  File "/usr/local/lib/python3.10/dist-packages/django/utils/functional.py", line 47, in __get__
    res = instance.__dict__[self.name] = self.func(instance)
  File "/usr/local/lib/python3.10/dist-packages/django/urls/resolvers.py", line 738, in url_patterns
    patterns = getattr(self.urlconf_module, "urlpatterns", self.urlconf_module)
  File "/usr/local/lib/python3.10/dist-packages/django/utils/functional.py", line 47, in __get__
    res = instance.__dict__[self.name] = self.func(instance)
  File "/usr/local/lib/python3.10/dist-packages/django/urls/resolvers.py", line 731, in urlconf_module
    return import_module(self.urlconf_name)
  File "/usr/lib/python3.10/importlib/__init__.py", line 126, in import_module
    return _bootstrap._gcd_import(name[level:], package, level)
  File "<frozen importlib._bootstrap>", line 1050, in _gcd_import
  File "<frozen importlib._bootstrap>", line 1027, in _find_and_load
  File "<frozen importlib._bootstrap>", line 1006, in _find_and_load_unlocked
  File "<frozen importlib._bootstrap>", line 688, in _load_unlocked
  File "<frozen importlib._bootstrap_external>", line 883, in exec_module
  File "<frozen importlib._bootstrap>", line 241, in _call_with_frames_removed
  File "/home/ubuntu/SEGroup6/猫猫就诊/Project/./backend/urls.py", line 19, in <module>
    from app01 import views
  File "/home/ubuntu/SEGroup6/猫猫就诊/Project/./app01/views.py", line 7, in <module>
    from rest_framework.views import APIView
ModuleNotFoundError: No module named 'rest_framework'

During handling of the above exception, another exception occurred:

Traceback (most recent call last):
  File "/usr/local/lib/python3.10/dist-packages/django/core/handlers/exception.py", line 55, in inner
    response = get_response(request)
  File "/usr/local/lib/python3.10/dist-packages/django/utils/deprecation.py", line 134, in __call__
    response = response or self.get_response(request)
  File "/usr/local/lib/python3.10/dist-packages/django/core/handlers/exception.py", line 57, in inner
    response = response_for_exception(request, exc)
  File "/usr/local/lib/python3.10/dist-packages/django/core/handlers/exception.py", line 140, in response_for_exception
    response = handle_uncaught_exception(
  File "/usr/local/lib/python3.10/dist-packages/django/core/handlers/exception.py", line 181, in handle_uncaught_exception
    return debug.technical_500_response(request, *exc_info)
  File "/usr/local/lib/python3.10/dist-packages/django/views/debug.py", line 69, in technical_500_response
    html = reporter.get_traceback_html()
  File "/usr/local/lib/python3.10/dist-packages/django/views/debug.py", line 428, in get_traceback_html
    c = Context(self.get_traceback_data(), use_l10n=False)
  File "/usr/local/lib/python3.10/dist-packages/django/views/debug.py", line 411, in get_traceback_data
    c["raising_view_name"] = get_caller(self.request)
  File "/usr/local/lib/python3.10/dist-packages/django/views/debug.py", line 102, in get_caller
    resolver_match = resolve(request.path)
  File "/usr/local/lib/python3.10/dist-packages/django/urls/base.py", line 24, in resolve
    return get_resolver(urlconf).resolve(path)
  File "/usr/local/lib/python3.10/dist-packages/django/urls/resolvers.py", line 686, in resolve
    for pattern in self.url_patterns:
  File "/usr/local/lib/python3.10/dist-packages/django/utils/functional.py", line 47, in __get__
    res = instance.__dict__[self.name] = self.func(instance)
  File "/usr/local/lib/python3.10/dist-packages/django/urls/resolvers.py", line 738, in url_patterns
    patterns = getattr(self.urlconf_module, "urlpatterns", self.urlconf_module)
  File "/usr/local/lib/python3.10/dist-packages/django/utils/functional.py", line 47, in __get__
    res = instance.__dict__[self.name] = self.func(instance)
  File "/usr/local/lib/python3.10/dist-packages/django/urls/resolvers.py", line 731, in urlconf_module
Traceback (most recent call last):
  File "/usr/local/lib/python3.10/dist-packages/django/core/handlers/exception.py", line 55, in inner
    return import_module(self.urlconf_name)
  File "/usr/lib/python3.10/importlib/__init__.py", line 126, in import_module
    response = get_response(request)
  File "/usr/local/lib/python3.10/dist-packages/django/core/handlers/base.py", line 181, in _get_response
    return _bootstrap._gcd_import(name[level:], package, level)
  File "<frozen importlib._bootstrap>", line 1050, in _gcd_import
    callback, callback_args, callback_kwargs = self.resolve_request(request)
  File "/usr/local/lib/python3.10/dist-packages/django/core/handlers/base.py", line 313, in resolve_request
  File "<frozen importlib._bootstrap>", line 1027, in _find_and_load
  File "<frozen importlib._bootstrap>", line 1006, in _find_and_load_unlocked
    resolver_match = resolver.resolve(request.path_info)
  File "/usr/local/lib/python3.10/dist-packages/django/urls/resolvers.py", line 686, in resolve
  File "<frozen importlib._bootstrap>", line 688, in _load_unlocked
  File "<frozen importlib._bootstrap_external>", line 883, in exec_module
  File "<frozen importlib._bootstrap>", line 241, in _call_with_frames_removed
  File "/home/ubuntu/SEGroup6/猫猫就诊/Project/./backend/urls.py", line 19, in <module>
    from app01 import views
  File "/home/ubuntu/SEGroup6/猫猫就诊/Project/./app01/views.py", line 7, in <module>
    for pattern in self.url_patterns:
  File "/usr/local/lib/python3.10/dist-packages/django/utils/functional.py", line 47, in __get__
    from rest_framework.views import APIView
ModuleNotFoundError: No module named 'rest_framework'

During handling of the above exception, another exception occurred:

Traceback (most recent call last):
  File "/usr/local/lib/python3.10/dist-packages/django/core/handlers/exception.py", line 55, in inner
    res = instance.__dict__[self.name] = self.func(instance)
  File "/usr/local/lib/python3.10/dist-packages/django/urls/resolvers.py", line 738, in url_patterns
    response = get_response(request)
  File "/usr/local/lib/python3.10/dist-packages/django/utils/deprecation.py", line 134, in __call__
    response = response or self.get_response(request)
  File "/usr/local/lib/python3.10/dist-packages/django/core/handlers/exception.py", line 57, in inner
    response = response_for_exception(request, exc)
  File "/usr/local/lib/python3.10/dist-packages/django/core/handlers/exception.py", line 140, in response_for_exception
    response = handle_uncaught_exception(
  File "/usr/local/lib/python3.10/dist-packages/django/core/handlers/exception.py", line 181, in handle_uncaught_exception
    patterns = getattr(self.urlconf_module, "urlpatterns", self.urlconf_module)
  File "/usr/local/lib/python3.10/dist-packages/django/utils/functional.py", line 47, in __get__
    return debug.technical_500_response(request, *exc_info)
  File "/usr/local/lib/python3.10/dist-packages/django/views/debug.py", line 69, in technical_500_response
    res = instance.__dict__[self.name] = self.func(instance)
  File "/usr/local/lib/python3.10/dist-packages/django/urls/resolvers.py", line 731, in urlconf_module
    html = reporter.get_traceback_html()
  File "/usr/local/lib/python3.10/dist-packages/django/views/debug.py", line 428, in get_traceback_html
    c = Context(self.get_traceback_data(), use_l10n=False)
  File "/usr/local/lib/python3.10/dist-packages/django/views/debug.py", line 411, in get_traceback_data
    return import_module(self.urlconf_name)
  File "/usr/lib/python3.10/importlib/__init__.py", line 126, in import_module
    return _bootstrap._gcd_import(name[level:], package, level)
  File "<frozen importlib._bootstrap>", line 1050, in _gcd_import
    c["raising_view_name"] = get_caller(self.request)
  File "/usr/local/lib/python3.10/dist-packages/django/views/debug.py", line 102, in get_caller
  File "<frozen importlib._bootstrap>", line 1027, in _find_and_load
    resolver_match = resolve(request.path)
  File "/usr/local/lib/python3.10/dist-packages/django/urls/base.py", line 24, in resolve
  File "<frozen importlib._bootstrap>", line 1006, in _find_and_load_unlocked
    return get_resolver(urlconf).resolve(path)
  File "/usr/local/lib/python3.10/dist-packages/django/urls/resolvers.py", line 686, in resolve
  File "<frozen importlib._bootstrap>", line 688, in _load_unlocked
  File "<frozen importlib._bootstrap_external>", line 883, in exec_module
  File "<frozen importlib._bootstrap>", line 241, in _call_with_frames_removed
  File "/home/ubuntu/SEGroup6/猫猫就诊/Project/./backend/urls.py", line 19, in <module>
    from app01 import views
  File "/home/ubuntu/SEGroup6/猫猫就诊/Project/./app01/views.py", line 7, in <module>
    for pattern in self.url_patterns:
  File "/usr/local/lib/python3.10/dist-packages/django/utils/functional.py", line 47, in __get__
    from rest_framework.views import APIView
ModuleNotFoundError: No module named 'rest_framework'
    res = instance.__dict__[self.name] = self.func(instance)

During handling of the above exception, another exception occurred:

  File "/usr/local/lib/python3.10/dist-packages/django/urls/resolvers.py", line 738, in url_patterns
Traceback (most recent call last):
  File "/usr/local/lib/python3.10/dist-packages/django/core/handlers/exception.py", line 55, in inner
    response = get_response(request)
  File "/usr/local/lib/python3.10/dist-packages/django/utils/deprecation.py", line 134, in __call__
    response = response or self.get_response(request)
  File "/usr/local/lib/python3.10/dist-packages/django/core/handlers/exception.py", line 57, in inner
    response = response_for_exception(request, exc)
  File "/usr/local/lib/python3.10/dist-packages/django/core/handlers/exception.py", line 140, in response_for_exception
    patterns = getattr(self.urlconf_module, "urlpatterns", self.urlconf_module)
    response = handle_uncaught_exception(
  File "/usr/local/lib/python3.10/dist-packages/django/utils/functional.py", line 47, in __get__
  File "/usr/local/lib/python3.10/dist-packages/django/core/handlers/exception.py", line 181, in handle_uncaught_exception
    res = instance.__dict__[self.name] = self.func(instance)
  File "/usr/local/lib/python3.10/dist-packages/django/urls/resolvers.py", line 731, in urlconf_module
    return debug.technical_500_response(request, *exc_info)
  File "/usr/local/lib/python3.10/dist-packages/django/views/debug.py", line 69, in technical_500_response
    html = reporter.get_traceback_html()
  File "/usr/local/lib/python3.10/dist-packages/django/views/debug.py", line 428, in get_traceback_html
    return import_module(self.urlconf_name)
  File "/usr/lib/python3.10/importlib/__init__.py", line 126, in import_module
    c = Context(self.get_traceback_data(), use_l10n=False)
  File "/usr/local/lib/python3.10/dist-packages/django/views/debug.py", line 411, in get_traceback_data
    return _bootstrap._gcd_import(name[level:], package, level)
  File "<frozen importlib._bootstrap>", line 1050, in _gcd_import
  File "<frozen importlib._bootstrap>", line 1027, in _find_and_load
    c["raising_view_name"] = get_caller(self.request)
  File "/usr/local/lib/python3.10/dist-packages/django/views/debug.py", line 102, in get_caller
  File "<frozen importlib._bootstrap>", line 1006, in _find_and_load_unlocked
  File "<frozen importlib._bootstrap>", line 688, in _load_unlocked
    resolver_match = resolve(request.path)
  File "/usr/local/lib/python3.10/dist-packages/django/urls/base.py", line 24, in resolve
  File "<frozen importlib._bootstrap_external>", line 883, in exec_module
    return get_resolver(urlconf).resolve(path)
  File "/usr/local/lib/python3.10/dist-packages/django/urls/resolvers.py", line 686, in resolve
  File "<frozen importlib._bootstrap>", line 241, in _call_with_frames_removed
  File "/home/ubuntu/SEGroup6/猫猫就诊/Project/./backend/urls.py", line 19, in <module>
    from app01 import views
  File "/home/ubuntu/SEGroup6/猫猫就诊/Project/./app01/views.py", line 7, in <module>
    from rest_framework.views import APIView
ModuleNotFoundError: No module named 'rest_framework'

During handling of the above exception, another exception occurred:

Traceback (most recent call last):
  File "/usr/local/lib/python3.10/dist-packages/django/core/handlers/exception.py", line 55, in inner
    for pattern in self.url_patterns:
  File "/usr/local/lib/python3.10/dist-packages/django/utils/functional.py", line 47, in __get__
    response = get_response(request)
  File "/usr/local/lib/python3.10/dist-packages/corsheaders/middleware.py", line 56, in __call__
    res = instance.__dict__[self.name] = self.func(instance)
  File "/usr/local/lib/python3.10/dist-packages/django/urls/resolvers.py", line 738, in url_patterns
    result = self.get_response(request)
  File "/usr/local/lib/python3.10/dist-packages/django/core/handlers/exception.py", line 57, in inner
    response = response_for_exception(request, exc)
  File "/usr/local/lib/python3.10/dist-packages/django/core/handlers/exception.py", line 140, in response_for_exception
    response = handle_uncaught_exception(
  File "/usr/local/lib/python3.10/dist-packages/django/core/handlers/exception.py", line 181, in handle_uncaught_exception
    return debug.technical_500_response(request, *exc_info)
  File "/usr/local/lib/python3.10/dist-packages/django/views/debug.py", line 69, in technical_500_response
    patterns = getattr(self.urlconf_module, "urlpatterns", self.urlconf_module)
  File "/usr/local/lib/python3.10/dist-packages/django/utils/functional.py", line 47, in __get__
    html = reporter.get_traceback_html()
  File "/usr/local/lib/python3.10/dist-packages/django/views/debug.py", line 428, in get_traceback_html
    res = instance.__dict__[self.name] = self.func(instance)
  File "/usr/local/lib/python3.10/dist-packages/django/urls/resolvers.py", line 731, in urlconf_module
    c = Context(self.get_traceback_data(), use_l10n=False)
  File "/usr/local/lib/python3.10/dist-packages/django/views/debug.py", line 411, in get_traceback_data
    return import_module(self.urlconf_name)
  File "/usr/lib/python3.10/importlib/__init__.py", line 126, in import_module
    c["raising_view_name"] = get_caller(self.request)
  File "/usr/local/lib/python3.10/dist-packages/django/views/debug.py", line 102, in get_caller
    return _bootstrap._gcd_import(name[level:], package, level)
  File "<frozen importlib._bootstrap>", line 1050, in _gcd_import
    resolver_match = resolve(request.path)
  File "<frozen importlib._bootstrap>", line 1027, in _find_and_load
  File "/usr/local/lib/python3.10/dist-packages/django/urls/base.py", line 24, in resolve
    return get_resolver(urlconf).resolve(path)
  File "<frozen importlib._bootstrap>", line 1006, in _find_and_load_unlocked
  File "/usr/local/lib/python3.10/dist-packages/django/urls/resolvers.py", line 686, in resolve
  File "<frozen importlib._bootstrap>", line 688, in _load_unlocked
  File "<frozen importlib._bootstrap_external>", line 883, in exec_module
  File "<frozen importlib._bootstrap>", line 241, in _call_with_frames_removed
  File "/home/ubuntu/SEGroup6/猫猫就诊/Project/./backend/urls.py", line 19, in <module>
    for pattern in self.url_patterns:
    from app01 import views
  File "/usr/local/lib/python3.10/dist-packages/django/utils/functional.py", line 47, in __get__
  File "/home/ubuntu/SEGroup6/猫猫就诊/Project/./app01/views.py", line 7, in <module>
    res = instance.__dict__[self.name] = self.func(instance)
    from rest_framework.views import APIView
  File "/usr/local/lib/python3.10/dist-packages/django/urls/resolvers.py", line 738, in url_patterns
ModuleNotFoundError: No module named 'rest_framework'

During handling of the above exception, another exception occurred:

Traceback (most recent call last):
  File "/usr/local/lib/python3.10/dist-packages/django/core/handlers/exception.py", line 55, in inner
    response = get_response(request)
  File "/usr/local/lib/python3.10/dist-packages/django/utils/deprecation.py", line 134, in __call__
    response = response or self.get_response(request)
  File "/usr/local/lib/python3.10/dist-packages/django/core/handlers/exception.py", line 57, in inner
    response = response_for_exception(request, exc)
  File "/usr/local/lib/python3.10/dist-packages/django/core/handlers/exception.py", line 140, in response_for_exception
    patterns = getattr(self.urlconf_module, "urlpatterns", self.urlconf_module)
  File "/usr/local/lib/python3.10/dist-packages/django/utils/functional.py", line 47, in __get__
    response = handle_uncaught_exception(
  File "/usr/local/lib/python3.10/dist-packages/django/core/handlers/exception.py", line 181, in handle_uncaught_exception
    res = instance.__dict__[self.name] = self.func(instance)
  File "/usr/local/lib/python3.10/dist-packages/django/urls/resolvers.py", line 731, in urlconf_module
    return debug.technical_500_response(request, *exc_info)
  File "/usr/local/lib/python3.10/dist-packages/django/views/debug.py", line 69, in technical_500_response
    html = reporter.get_traceback_html()
  File "/usr/local/lib/python3.10/dist-packages/django/views/debug.py", line 428, in get_traceback_html
    return import_module(self.urlconf_name)
  File "/usr/lib/python3.10/importlib/__init__.py", line 126, in import_module
    c = Context(self.get_traceback_data(), use_l10n=False)
  File "/usr/local/lib/python3.10/dist-packages/django/views/debug.py", line 411, in get_traceback_data
    return _bootstrap._gcd_import(name[level:], package, level)
  File "<frozen importlib._bootstrap>", line 1050, in _gcd_import
  File "<frozen importlib._bootstrap>", line 1027, in _find_and_load
    c["raising_view_name"] = get_caller(self.request)
  File "<frozen importlib._bootstrap>", line 1006, in _find_and_load_unlocked
  File "/usr/local/lib/python3.10/dist-packages/django/views/debug.py", line 102, in get_caller
  File "<frozen importlib._bootstrap>", line 688, in _load_unlocked
    resolver_match = resolve(request.path)
  File "/usr/local/lib/python3.10/dist-packages/django/urls/base.py", line 24, in resolve
  File "<frozen importlib._bootstrap_external>", line 883, in exec_module
    return get_resolver(urlconf).resolve(path)
  File "/usr/local/lib/python3.10/dist-packages/django/urls/resolvers.py", line 686, in resolve
  File "<frozen importlib._bootstrap>", line 241, in _call_with_frames_removed
  File "/home/ubuntu/SEGroup6/猫猫就诊/Project/./backend/urls.py", line 19, in <module>
    from app01 import views
  File "/home/ubuntu/SEGroup6/猫猫就诊/Project/./app01/views.py", line 7, in <module>
    from rest_framework.views import APIView
ModuleNotFoundError: No module named 'rest_framework'

During handling of the above exception, another exception occurred:

Traceback (most recent call last):
  File "/usr/local/lib/python3.10/dist-packages/django/core/handlers/exception.py", line 55, in inner
    for pattern in self.url_patterns:
  File "/usr/local/lib/python3.10/dist-packages/django/utils/functional.py", line 47, in __get__
    response = get_response(request)
  File "/usr/local/lib/python3.10/dist-packages/django/utils/deprecation.py", line 134, in __call__
    res = instance.__dict__[self.name] = self.func(instance)
  File "/usr/local/lib/python3.10/dist-packages/django/urls/resolvers.py", line 738, in url_patterns
    response = response or self.get_response(request)
  File "/usr/local/lib/python3.10/dist-packages/django/core/handlers/exception.py", line 57, in inner
    response = response_for_exception(request, exc)
  File "/usr/local/lib/python3.10/dist-packages/django/core/handlers/exception.py", line 140, in response_for_exception
    response = handle_uncaught_exception(
  File "/usr/local/lib/python3.10/dist-packages/django/core/handlers/exception.py", line 181, in handle_uncaught_exception
    patterns = getattr(self.urlconf_module, "urlpatterns", self.urlconf_module)
  File "/usr/local/lib/python3.10/dist-packages/django/utils/functional.py", line 47, in __get__
    return debug.technical_500_response(request, *exc_info)
  File "/usr/local/lib/python3.10/dist-packages/django/views/debug.py", line 69, in technical_500_response
    res = instance.__dict__[self.name] = self.func(instance)
  File "/usr/local/lib/python3.10/dist-packages/django/urls/resolvers.py", line 731, in urlconf_module
    html = reporter.get_traceback_html()
  File "/usr/local/lib/python3.10/dist-packages/django/views/debug.py", line 428, in get_traceback_html
    c = Context(self.get_traceback_data(), use_l10n=False)
  File "/usr/local/lib/python3.10/dist-packages/django/views/debug.py", line 411, in get_traceback_data
    return import_module(self.urlconf_name)
  File "/usr/lib/python3.10/importlib/__init__.py", line 126, in import_module
    return _bootstrap._gcd_import(name[level:], package, level)
  File "<frozen importlib._bootstrap>", line 1050, in _gcd_import
    c["raising_view_name"] = get_caller(self.request)
  File "/usr/local/lib/python3.10/dist-packages/django/views/debug.py", line 102, in get_caller
  File "<frozen importlib._bootstrap>", line 1027, in _find_and_load
    resolver_match = resolve(request.path)
  File "/usr/local/lib/python3.10/dist-packages/django/urls/base.py", line 24, in resolve
    return get_resolver(urlconf).resolve(path)
  File "/usr/local/lib/python3.10/dist-packages/django/urls/resolvers.py", line 686, in resolve
  File "<frozen importlib._bootstrap>", line 1006, in _find_and_load_unlocked
  File "<frozen importlib._bootstrap>", line 688, in _load_unlocked
  File "<frozen importlib._bootstrap_external>", line 883, in exec_module
  File "<frozen importlib._bootstrap>", line 241, in _call_with_frames_removed
  File "/home/ubuntu/SEGroup6/猫猫就诊/Project/./backend/urls.py", line 19, in <module>
    for pattern in self.url_patterns:
  File "/usr/local/lib/python3.10/dist-packages/django/utils/functional.py", line 47, in __get__
    from app01 import views
  File "/home/ubuntu/SEGroup6/猫猫就诊/Project/./app01/views.py", line 7, in <module>
    res = instance.__dict__[self.name] = self.func(instance)
  File "/usr/local/lib/python3.10/dist-packages/django/urls/resolvers.py", line 738, in url_patterns
    from rest_framework.views import APIView
ModuleNotFoundError: No module named 'rest_framework'

During handling of the above exception, another exception occurred:

Traceback (most recent call last):
  File "/usr/local/lib/python3.10/dist-packages/django/core/handlers/exception.py", line 55, in inner
    response = get_response(request)
  File "/usr/local/lib/python3.10/dist-packages/django/utils/deprecation.py", line 134, in __call__
    response = response or self.get_response(request)
  File "/usr/local/lib/python3.10/dist-packages/django/core/handlers/exception.py", line 57, in inner
    response = response_for_exception(request, exc)
  File "/usr/local/lib/python3.10/dist-packages/django/core/handlers/exception.py", line 140, in response_for_exception
    response = handle_uncaught_exception(
  File "/usr/local/lib/python3.10/dist-packages/django/core/handlers/exception.py", line 181, in handle_uncaught_exception
    patterns = getattr(self.urlconf_module, "urlpatterns", self.urlconf_module)
  File "/usr/local/lib/python3.10/dist-packages/django/utils/functional.py", line 47, in __get__
    res = instance.__dict__[self.name] = self.func(instance)
  File "/usr/local/lib/python3.10/dist-packages/django/urls/resolvers.py", line 731, in urlconf_module
    return debug.technical_500_response(request, *exc_info)
  File "/usr/local/lib/python3.10/dist-packages/django/views/debug.py", line 69, in technical_500_response
    html = reporter.get_traceback_html()
  File "/usr/local/lib/python3.10/dist-packages/django/views/debug.py", line 428, in get_traceback_html
    return import_module(self.urlconf_name)
  File "/usr/lib/python3.10/importlib/__init__.py", line 126, in import_module
    return _bootstrap._gcd_import(name[level:], package, level)
  File "<frozen importlib._bootstrap>", line 1050, in _gcd_import
    c = Context(self.get_traceback_data(), use_l10n=False)
  File "/usr/local/lib/python3.10/dist-packages/django/views/debug.py", line 411, in get_traceback_data
  File "<frozen importlib._bootstrap>", line 1027, in _find_and_load
  File "<frozen importlib._bootstrap>", line 1006, in _find_and_load_unlocked
    c["raising_view_name"] = get_caller(self.request)
  File "/usr/local/lib/python3.10/dist-packages/django/views/debug.py", line 102, in get_caller
  File "<frozen importlib._bootstrap>", line 688, in _load_unlocked
    resolver_match = resolve(request.path)
  File "/usr/local/lib/python3.10/dist-packages/django/urls/base.py", line 24, in resolve
  File "<frozen importlib._bootstrap_external>", line 883, in exec_module
    return get_resolver(urlconf).resolve(path)
  File "/usr/local/lib/python3.10/dist-packages/django/urls/resolvers.py", line 686, in resolve
  File "<frozen importlib._bootstrap>", line 241, in _call_with_frames_removed
  File "/home/ubuntu/SEGroup6/猫猫就诊/Project/./backend/urls.py", line 19, in <module>
    from app01 import views
  File "/home/ubuntu/SEGroup6/猫猫就诊/Project/./app01/views.py", line 7, in <module>
    from rest_framework.views import APIView
ModuleNotFoundError: No module named 'rest_framework'

During handling of the above exception, another exception occurred:

Traceback (most recent call last):
  File "/usr/local/lib/python3.10/dist-packages/django/core/handlers/exception.py", line 55, in inner
    response = get_response(request)
  File "/usr/local/lib/python3.10/dist-packages/django/utils/deprecation.py", line 134, in __call__
    for pattern in self.url_patterns:
  File "/usr/local/lib/python3.10/dist-packages/django/utils/functional.py", line 47, in __get__
    res = instance.__dict__[self.name] = self.func(instance)
  File "/usr/local/lib/python3.10/dist-packages/django/urls/resolvers.py", line 738, in url_patterns
    response = response or self.get_response(request)
  File "/usr/local/lib/python3.10/dist-packages/django/core/handlers/exception.py", line 57, in inner
    response = response_for_exception(request, exc)
  File "/usr/local/lib/python3.10/dist-packages/django/core/handlers/exception.py", line 140, in response_for_exception
    response = handle_uncaught_exception(
  File "/usr/local/lib/python3.10/dist-packages/django/core/handlers/exception.py", line 181, in handle_uncaught_exception
    return debug.technical_500_response(request, *exc_info)
  File "/usr/local/lib/python3.10/dist-packages/django/views/debug.py", line 69, in technical_500_response
    patterns = getattr(self.urlconf_module, "urlpatterns", self.urlconf_module)
  File "/usr/local/lib/python3.10/dist-packages/django/utils/functional.py", line 47, in __get__
    html = reporter.get_traceback_html()
  File "/usr/local/lib/python3.10/dist-packages/django/views/debug.py", line 428, in get_traceback_html
    res = instance.__dict__[self.name] = self.func(instance)
  File "/usr/local/lib/python3.10/dist-packages/django/urls/resolvers.py", line 731, in urlconf_module
    c = Context(self.get_traceback_data(), use_l10n=False)
  File "/usr/local/lib/python3.10/dist-packages/django/views/debug.py", line 411, in get_traceback_data
    return import_module(self.urlconf_name)
  File "/usr/lib/python3.10/importlib/__init__.py", line 126, in import_module
    c["raising_view_name"] = get_caller(self.request)
  File "/usr/local/lib/python3.10/dist-packages/django/views/debug.py", line 102, in get_caller
    return _bootstrap._gcd_import(name[level:], package, level)
  File "<frozen importlib._bootstrap>", line 1050, in _gcd_import
    resolver_match = resolve(request.path)
  File "/usr/local/lib/python3.10/dist-packages/django/urls/base.py", line 24, in resolve
  File "<frozen importlib._bootstrap>", line 1027, in _find_and_load
    return get_resolver(urlconf).resolve(path)
  File "/usr/local/lib/python3.10/dist-packages/django/urls/resolvers.py", line 686, in resolve
  File "<frozen importlib._bootstrap>", line 1006, in _find_and_load_unlocked
  File "<frozen importlib._bootstrap>", line 688, in _load_unlocked
  File "<frozen importlib._bootstrap_external>", line 883, in exec_module
  File "<frozen importlib._bootstrap>", line 241, in _call_with_frames_removed
  File "/home/ubuntu/SEGroup6/猫猫就诊/Project/./backend/urls.py", line 19, in <module>
    for pattern in self.url_patterns:
  File "/usr/local/lib/python3.10/dist-packages/django/utils/functional.py", line 47, in __get__
    from app01 import views
  File "/home/ubuntu/SEGroup6/猫猫就诊/Project/./app01/views.py", line 7, in <module>
    res = instance.__dict__[self.name] = self.func(instance)
  File "/usr/local/lib/python3.10/dist-packages/django/urls/resolvers.py", line 738, in url_patterns
    from rest_framework.views import APIView
ModuleNotFoundError: No module named 'rest_framework'

During handling of the above exception, another exception occurred:

Traceback (most recent call last):
  File "/usr/local/lib/python3.10/dist-packages/django/core/handlers/exception.py", line 55, in inner
    response = get_response(request)
  File "/usr/local/lib/python3.10/dist-packages/django/utils/deprecation.py", line 134, in __call__
    response = response or self.get_response(request)
  File "/usr/local/lib/python3.10/dist-packages/django/core/handlers/exception.py", line 57, in inner
    response = response_for_exception(request, exc)
  File "/usr/local/lib/python3.10/dist-packages/django/core/handlers/exception.py", line 140, in response_for_exception
    patterns = getattr(self.urlconf_module, "urlpatterns", self.urlconf_module)
  File "/usr/local/lib/python3.10/dist-packages/django/utils/functional.py", line 47, in __get__
    response = handle_uncaught_exception(
  File "/usr/local/lib/python3.10/dist-packages/django/core/handlers/exception.py", line 181, in handle_uncaught_exception
    res = instance.__dict__[self.name] = self.func(instance)
  File "/usr/local/lib/python3.10/dist-packages/django/urls/resolvers.py", line 731, in urlconf_module
    return debug.technical_500_response(request, *exc_info)
  File "/usr/local/lib/python3.10/dist-packages/django/views/debug.py", line 69, in technical_500_response
    html = reporter.get_traceback_html()
  File "/usr/local/lib/python3.10/dist-packages/django/views/debug.py", line 428, in get_traceback_html
    return import_module(self.urlconf_name)
  File "/usr/lib/python3.10/importlib/__init__.py", line 126, in import_module
    c = Context(self.get_traceback_data(), use_l10n=False)
  File "/usr/local/lib/python3.10/dist-packages/django/views/debug.py", line 411, in get_traceback_data
    return _bootstrap._gcd_import(name[level:], package, level)
  File "<frozen importlib._bootstrap>", line 1050, in _gcd_import
  File "<frozen importlib._bootstrap>", line 1027, in _find_and_load
  File "<frozen importlib._bootstrap>", line 1006, in _find_and_load_unlocked
    c["raising_view_name"] = get_caller(self.request)
  File "/usr/local/lib/python3.10/dist-packages/django/views/debug.py", line 102, in get_caller
  File "<frozen importlib._bootstrap>", line 688, in _load_unlocked
    resolver_match = resolve(request.path)
  File "/usr/local/lib/python3.10/dist-packages/django/urls/base.py", line 24, in resolve
  File "<frozen importlib._bootstrap_external>", line 883, in exec_module
    return get_resolver(urlconf).resolve(path)
  File "/usr/local/lib/python3.10/dist-packages/django/urls/resolvers.py", line 686, in resolve
  File "<frozen importlib._bootstrap>", line 241, in _call_with_frames_removed
  File "/home/ubuntu/SEGroup6/猫猫就诊/Project/./backend/urls.py", line 19, in <module>
    from app01 import views
  File "/home/ubuntu/SEGroup6/猫猫就诊/Project/./app01/views.py", line 7, in <module>
    from rest_framework.views import APIView
ModuleNotFoundError: No module named 'rest_framework'

During handling of the above exception, another exception occurred:

Traceback (most recent call last):
  File "/usr/local/lib/python3.10/dist-packages/django/core/handlers/wsgi.py", line 124, in __call__
    for pattern in self.url_patterns:
  File "/usr/local/lib/python3.10/dist-packages/django/utils/functional.py", line 47, in __get__
    response = self.get_response(request)
  File "/usr/local/lib/python3.10/dist-packages/django/core/handlers/base.py", line 140, in get_response
    res = instance.__dict__[self.name] = self.func(instance)
  File "/usr/local/lib/python3.10/dist-packages/django/urls/resolvers.py", line 738, in url_patterns
    response = self._middleware_chain(request)
  File "/usr/local/lib/python3.10/dist-packages/django/core/handlers/exception.py", line 57, in inner
    response = response_for_exception(request, exc)
  File "/usr/local/lib/python3.10/dist-packages/django/core/handlers/exception.py", line 140, in response_for_exception
    response = handle_uncaught_exception(
  File "/usr/local/lib/python3.10/dist-packages/django/core/handlers/exception.py", line 181, in handle_uncaught_exception
    return debug.technical_500_response(request, *exc_info)
  File "/usr/local/lib/python3.10/dist-packages/django/views/debug.py", line 69, in technical_500_response
    patterns = getattr(self.urlconf_module, "urlpatterns", self.urlconf_module)
    html = reporter.get_traceback_html()
  File "/usr/local/lib/python3.10/dist-packages/django/utils/functional.py", line 47, in __get__
  File "/usr/local/lib/python3.10/dist-packages/django/views/debug.py", line 428, in get_traceback_html
    res = instance.__dict__[self.name] = self.func(instance)
  File "/usr/local/lib/python3.10/dist-packages/django/urls/resolvers.py", line 731, in urlconf_module
    c = Context(self.get_traceback_data(), use_l10n=False)
  File "/usr/local/lib/python3.10/dist-packages/django/views/debug.py", line 411, in get_traceback_data
    return import_module(self.urlconf_name)
  File "/usr/lib/python3.10/importlib/__init__.py", line 126, in import_module
    c["raising_view_name"] = get_caller(self.request)
  File "/usr/local/lib/python3.10/dist-packages/django/views/debug.py", line 102, in get_caller
    return _bootstrap._gcd_import(name[level:], package, level)
  File "<frozen importlib._bootstrap>", line 1050, in _gcd_import
    resolver_match = resolve(request.path)
  File "/usr/local/lib/python3.10/dist-packages/django/urls/base.py", line 24, in resolve
  File "<frozen importlib._bootstrap>", line 1027, in _find_and_load
    return get_resolver(urlconf).resolve(path)
  File "/usr/local/lib/python3.10/dist-packages/django/urls/resolvers.py", line 686, in resolve
  File "<frozen importlib._bootstrap>", line 1006, in _find_and_load_unlocked
  File "<frozen importlib._bootstrap>", line 688, in _load_unlocked
  File "<frozen importlib._bootstrap_external>", line 883, in exec_module
  File "<frozen importlib._bootstrap>", line 241, in _call_with_frames_removed
    for pattern in self.url_patterns:
  File "/usr/local/lib/python3.10/dist-packages/django/utils/functional.py", line 47, in __get__
  File "/home/ubuntu/SEGroup6/猫猫就诊/Project/./backend/urls.py", line 19, in <module>
    res = instance.__dict__[self.name] = self.func(instance)
  File "/usr/local/lib/python3.10/dist-packages/django/urls/resolvers.py", line 738, in url_patterns
    from app01 import views
  File "/home/ubuntu/SEGroup6/猫猫就诊/Project/./app01/views.py", line 7, in <module>
    from rest_framework.views import APIView
ModuleNotFoundError: No module named 'rest_framework'

During handling of the above exception, another exception occurred:

Traceback (most recent call last):
  File "/usr/local/lib/python3.10/dist-packages/django/core/handlers/exception.py", line 55, in inner
    response = get_response(request)
  File "/usr/local/lib/python3.10/dist-packages/corsheaders/middleware.py", line 56, in __call__
    result = self.get_response(request)
  File "/usr/local/lib/python3.10/dist-packages/django/core/handlers/exception.py", line 57, in inner
    response = response_for_exception(request, exc)
    patterns = getattr(self.urlconf_module, "urlpatterns", self.urlconf_module)
  File "/usr/local/lib/python3.10/dist-packages/django/core/handlers/exception.py", line 140, in response_for_exception
  File "/usr/local/lib/python3.10/dist-packages/django/utils/functional.py", line 47, in __get__
    res = instance.__dict__[self.name] = self.func(instance)
  File "/usr/local/lib/python3.10/dist-packages/django/urls/resolvers.py", line 731, in urlconf_module
    response = handle_uncaught_exception(
  File "/usr/local/lib/python3.10/dist-packages/django/core/handlers/exception.py", line 181, in handle_uncaught_exception
    return debug.technical_500_response(request, *exc_info)
  File "/usr/local/lib/python3.10/dist-packages/django/views/debug.py", line 69, in technical_500_response
    html = reporter.get_traceback_html()
  File "/usr/local/lib/python3.10/dist-packages/django/views/debug.py", line 428, in get_traceback_html
    return import_module(self.urlconf_name)
  File "/usr/lib/python3.10/importlib/__init__.py", line 126, in import_module
    return _bootstrap._gcd_import(name[level:], package, level)
  File "<frozen importlib._bootstrap>", line 1050, in _gcd_import
    c = Context(self.get_traceback_data(), use_l10n=False)
  File "/usr/local/lib/python3.10/dist-packages/django/views/debug.py", line 411, in get_traceback_data
  File "<frozen importlib._bootstrap>", line 1027, in _find_and_load
  File "<frozen importlib._bootstrap>", line 1006, in _find_and_load_unlocked
  File "<frozen importlib._bootstrap>", line 688, in _load_unlocked
  File "<frozen importlib._bootstrap_external>", line 883, in exec_module
    c["raising_view_name"] = get_caller(self.request)
  File "/usr/local/lib/python3.10/dist-packages/django/views/debug.py", line 102, in get_caller
  File "<frozen importlib._bootstrap>", line 241, in _call_with_frames_removed
    resolver_match = resolve(request.path)
  File "/usr/local/lib/python3.10/dist-packages/django/urls/base.py", line 24, in resolve
  File "/home/ubuntu/SEGroup6/猫猫就诊/Project/./backend/urls.py", line 19, in <module>
    return get_resolver(urlconf).resolve(path)
  File "/usr/local/lib/python3.10/dist-packages/django/urls/resolvers.py", line 686, in resolve
    from app01 import views
  File "/home/ubuntu/SEGroup6/猫猫就诊/Project/./app01/views.py", line 7, in <module>
    from rest_framework.views import APIView
ModuleNotFoundError: No module named 'rest_framework'
    for pattern in self.url_patterns:
  File "/usr/local/lib/python3.10/dist-packages/django/utils/functional.py", line 47, in __get__
[pid: 28595|app: 0|req: 1/1] 219.239.227.188 () {38 vars in 651 bytes} [Sun May 26 03:58:35 2024] GET /api/treatments/list/ => generated 0 bytes in 4416 msecs (HTTP/1.1 500) 0 headers in 0 bytes (0 switches on core 0)
    res = instance.__dict__[self.name] = self.func(instance)
  File "/usr/local/lib/python3.10/dist-packages/django/urls/resolvers.py", line 738, in url_patterns
    patterns = getattr(self.urlconf_module, "urlpatterns", self.urlconf_module)
  File "/usr/local/lib/python3.10/dist-packages/django/utils/functional.py", line 47, in __get__
    res = instance.__dict__[self.name] = self.func(instance)
  File "/usr/local/lib/python3.10/dist-packages/django/urls/resolvers.py", line 731, in urlconf_module
    return import_module(self.urlconf_name)
  File "/usr/lib/python3.10/importlib/__init__.py", line 126, in import_module
    return _bootstrap._gcd_import(name[level:], package, level)
  File "<frozen importlib._bootstrap>", line 1050, in _gcd_import
  File "<frozen importlib._bootstrap>", line 1027, in _find_and_load
  File "<frozen importlib._bootstrap>", line 1006, in _find_and_load_unlocked
  File "<frozen importlib._bootstrap>", line 688, in _load_unlocked
  File "<frozen importlib._bootstrap_external>", line 883, in exec_module
  File "<frozen importlib._bootstrap>", line 241, in _call_with_frames_removed
  File "/home/ubuntu/SEGroup6/猫猫就诊/Project/./backend/urls.py", line 19, in <module>
    from app01 import views
  File "/home/ubuntu/SEGroup6/猫猫就诊/Project/./app01/views.py", line 7, in <module>
    from rest_framework.views import APIView
ModuleNotFoundError: No module named 'rest_framework'

During handling of the above exception, another exception occurred:

Traceback (most recent call last):
  File "/usr/local/lib/python3.10/dist-packages/django/core/handlers/exception.py", line 55, in inner
    response = get_response(request)
  File "/usr/local/lib/python3.10/dist-packages/django/utils/deprecation.py", line 134, in __call__
    response = response or self.get_response(request)
  File "/usr/local/lib/python3.10/dist-packages/django/core/handlers/exception.py", line 57, in inner
    response = response_for_exception(request, exc)
  File "/usr/local/lib/python3.10/dist-packages/django/core/handlers/exception.py", line 140, in response_for_exception
    response = handle_uncaught_exception(
  File "/usr/local/lib/python3.10/dist-packages/django/core/handlers/exception.py", line 181, in handle_uncaught_exception
    return debug.technical_500_response(request, *exc_info)
  File "/usr/local/lib/python3.10/dist-packages/django/views/debug.py", line 69, in technical_500_response
    html = reporter.get_traceback_html()
  File "/usr/local/lib/python3.10/dist-packages/django/views/debug.py", line 428, in get_traceback_html
    c = Context(self.get_traceback_data(), use_l10n=False)
  File "/usr/local/lib/python3.10/dist-packages/django/views/debug.py", line 411, in get_traceback_data
    c["raising_view_name"] = get_caller(self.request)
  File "/usr/local/lib/python3.10/dist-packages/django/views/debug.py", line 102, in get_caller
    resolver_match = resolve(request.path)
  File "/usr/local/lib/python3.10/dist-packages/django/urls/base.py", line 24, in resolve
    return get_resolver(urlconf).resolve(path)
  File "/usr/local/lib/python3.10/dist-packages/django/urls/resolvers.py", line 686, in resolve
    for pattern in self.url_patterns:
  File "/usr/local/lib/python3.10/dist-packages/django/utils/functional.py", line 47, in __get__
    res = instance.__dict__[self.name] = self.func(instance)
  File "/usr/local/lib/python3.10/dist-packages/django/urls/resolvers.py", line 738, in url_patterns
    patterns = getattr(self.urlconf_module, "urlpatterns", self.urlconf_module)
  File "/usr/local/lib/python3.10/dist-packages/django/utils/functional.py", line 47, in __get__
    res = instance.__dict__[self.name] = self.func(instance)
  File "/usr/local/lib/python3.10/dist-packages/django/urls/resolvers.py", line 731, in urlconf_module
    return import_module(self.urlconf_name)
  File "/usr/lib/python3.10/importlib/__init__.py", line 126, in import_module
    return _bootstrap._gcd_import(name[level:], package, level)
  File "<frozen importlib._bootstrap>", line 1050, in _gcd_import
  File "<frozen importlib._bootstrap>", line 1027, in _find_and_load
  File "<frozen importlib._bootstrap>", line 1006, in _find_and_load_unlocked
  File "<frozen importlib._bootstrap>", line 688, in _load_unlocked
  File "<frozen importlib._bootstrap_external>", line 883, in exec_module
  File "<frozen importlib._bootstrap>", line 241, in _call_with_frames_removed
  File "/home/ubuntu/SEGroup6/猫猫就诊/Project/./backend/urls.py", line 19, in <module>
    from app01 import views
  File "/home/ubuntu/SEGroup6/猫猫就诊/Project/./app01/views.py", line 7, in <module>
    from rest_framework.views import APIView
ModuleNotFoundError: No module named 'rest_framework'

During handling of the above exception, another exception occurred:

Traceback (most recent call last):
  File "/usr/local/lib/python3.10/dist-packages/django/core/handlers/exception.py", line 55, in inner
    response = get_response(request)
  File "/usr/local/lib/python3.10/dist-packages/django/utils/deprecation.py", line 134, in __call__
    response = response or self.get_response(request)
  File "/usr/local/lib/python3.10/dist-packages/django/core/handlers/exception.py", line 57, in inner
    response = response_for_exception(request, exc)
  File "/usr/local/lib/python3.10/dist-packages/django/core/handlers/exception.py", line 140, in response_for_exception
    response = handle_uncaught_exception(
  File "/usr/local/lib/python3.10/dist-packages/django/core/handlers/exception.py", line 181, in handle_uncaught_exception
    return debug.technical_500_response(request, *exc_info)
  File "/usr/local/lib/python3.10/dist-packages/django/views/debug.py", line 69, in technical_500_response
    html = reporter.get_traceback_html()
  File "/usr/local/lib/python3.10/dist-packages/django/views/debug.py", line 428, in get_traceback_html
    c = Context(self.get_traceback_data(), use_l10n=False)
  File "/usr/local/lib/python3.10/dist-packages/django/views/debug.py", line 411, in get_traceback_data
    c["raising_view_name"] = get_caller(self.request)
  File "/usr/local/lib/python3.10/dist-packages/django/views/debug.py", line 102, in get_caller
    resolver_match = resolve(request.path)
  File "/usr/local/lib/python3.10/dist-packages/django/urls/base.py", line 24, in resolve
    return get_resolver(urlconf).resolve(path)
  File "/usr/local/lib/python3.10/dist-packages/django/urls/resolvers.py", line 686, in resolve
    for pattern in self.url_patterns:
  File "/usr/local/lib/python3.10/dist-packages/django/utils/functional.py", line 47, in __get__
    res = instance.__dict__[self.name] = self.func(instance)
  File "/usr/local/lib/python3.10/dist-packages/django/urls/resolvers.py", line 738, in url_patterns
    patterns = getattr(self.urlconf_module, "urlpatterns", self.urlconf_module)
  File "/usr/local/lib/python3.10/dist-packages/django/utils/functional.py", line 47, in __get__
    res = instance.__dict__[self.name] = self.func(instance)
  File "/usr/local/lib/python3.10/dist-packages/django/urls/resolvers.py", line 731, in urlconf_module
    return import_module(self.urlconf_name)
  File "/usr/lib/python3.10/importlib/__init__.py", line 126, in import_module
    return _bootstrap._gcd_import(name[level:], package, level)
  File "<frozen importlib._bootstrap>", line 1050, in _gcd_import
  File "<frozen importlib._bootstrap>", line 1027, in _find_and_load
  File "<frozen importlib._bootstrap>", line 1006, in _find_and_load_unlocked
  File "<frozen importlib._bootstrap>", line 688, in _load_unlocked
  File "<frozen importlib._bootstrap_external>", line 883, in exec_module
  File "<frozen importlib._bootstrap>", line 241, in _call_with_frames_removed
  File "/home/ubuntu/SEGroup6/猫猫就诊/Project/./backend/urls.py", line 19, in <module>
    from app01 import views
  File "/home/ubuntu/SEGroup6/猫猫就诊/Project/./app01/views.py", line 7, in <module>
    from rest_framework.views import APIView
ModuleNotFoundError: No module named 'rest_framework'

During handling of the above exception, another exception occurred:

Traceback (most recent call last):
  File "/usr/local/lib/python3.10/dist-packages/django/core/handlers/wsgi.py", line 124, in __call__
    response = self.get_response(request)
  File "/usr/local/lib/python3.10/dist-packages/django/core/handlers/base.py", line 140, in get_response
    response = self._middleware_chain(request)
  File "/usr/local/lib/python3.10/dist-packages/django/core/handlers/exception.py", line 57, in inner
    response = response_for_exception(request, exc)
  File "/usr/local/lib/python3.10/dist-packages/django/core/handlers/exception.py", line 140, in response_for_exception
    response = handle_uncaught_exception(
  File "/usr/local/lib/python3.10/dist-packages/django/core/handlers/exception.py", line 181, in handle_uncaught_exception
    return debug.technical_500_response(request, *exc_info)
  File "/usr/local/lib/python3.10/dist-packages/django/views/debug.py", line 69, in technical_500_response
    html = reporter.get_traceback_html()
  File "/usr/local/lib/python3.10/dist-packages/django/views/debug.py", line 428, in get_traceback_html
    c = Context(self.get_traceback_data(), use_l10n=False)
  File "/usr/local/lib/python3.10/dist-packages/django/views/debug.py", line 411, in get_traceback_data
    c["raising_view_name"] = get_caller(self.request)
  File "/usr/local/lib/python3.10/dist-packages/django/views/debug.py", line 102, in get_caller
    resolver_match = resolve(request.path)
  File "/usr/local/lib/python3.10/dist-packages/django/urls/base.py", line 24, in resolve
    return get_resolver(urlconf).resolve(path)
  File "/usr/local/lib/python3.10/dist-packages/django/urls/resolvers.py", line 686, in resolve
    for pattern in self.url_patterns:
  File "/usr/local/lib/python3.10/dist-packages/django/utils/functional.py", line 47, in __get__
    res = instance.__dict__[self.name] = self.func(instance)
  File "/usr/local/lib/python3.10/dist-packages/django/urls/resolvers.py", line 738, in url_patterns
    patterns = getattr(self.urlconf_module, "urlpatterns", self.urlconf_module)
  File "/usr/local/lib/python3.10/dist-packages/django/utils/functional.py", line 47, in __get__
    res = instance.__dict__[self.name] = self.func(instance)
  File "/usr/local/lib/python3.10/dist-packages/django/urls/resolvers.py", line 731, in urlconf_module
    return import_module(self.urlconf_name)
  File "/usr/lib/python3.10/importlib/__init__.py", line 126, in import_module
    return _bootstrap._gcd_import(name[level:], package, level)
  File "<frozen importlib._bootstrap>", line 1050, in _gcd_import
  File "<frozen importlib._bootstrap>", line 1027, in _find_and_load
  File "<frozen importlib._bootstrap>", line 1006, in _find_and_load_unlocked
  File "<frozen importlib._bootstrap>", line 688, in _load_unlocked
  File "<frozen importlib._bootstrap_external>", line 883, in exec_module
  File "<frozen importlib._bootstrap>", line 241, in _call_with_frames_removed
  File "/home/ubuntu/SEGroup6/猫猫就诊/Project/./backend/urls.py", line 19, in <module>
    from app01 import views
  File "/home/ubuntu/SEGroup6/猫猫就诊/Project/./app01/views.py", line 7, in <module>
    from rest_framework.views import APIView
ModuleNotFoundError: No module named 'rest_framework'
[pid: 28594|app: 0|req: 1/2] 219.239.227.188 () {38 vars in 647 bytes} [Sun May 26 03:58:35 2024] GET /api/medicine/list/ => generated 0 bytes in 4423 msecs (HTTP/1.1 500) 0 headers in 0 bytes (0 switches on core 0)
Traceback (most recent call last):
  File "/usr/local/lib/python3.10/dist-packages/django/core/handlers/exception.py", line 55, in inner
    response = get_response(request)
  File "/usr/local/lib/python3.10/dist-packages/django/core/handlers/base.py", line 181, in _get_response
    callback, callback_args, callback_kwargs = self.resolve_request(request)
  File "/usr/local/lib/python3.10/dist-packages/django/core/handlers/base.py", line 313, in resolve_request
    resolver_match = resolver.resolve(request.path_info)
  File "/usr/local/lib/python3.10/dist-packages/django/urls/resolvers.py", line 686, in resolve
    for pattern in self.url_patterns:
  File "/usr/local/lib/python3.10/dist-packages/django/utils/functional.py", line 47, in __get__
    res = instance.__dict__[self.name] = self.func(instance)
  File "/usr/local/lib/python3.10/dist-packages/django/urls/resolvers.py", line 738, in url_patterns
    patterns = getattr(self.urlconf_module, "urlpatterns", self.urlconf_module)
  File "/usr/local/lib/python3.10/dist-packages/django/utils/functional.py", line 47, in __get__
    res = instance.__dict__[self.name] = self.func(instance)
  File "/usr/local/lib/python3.10/dist-packages/django/urls/resolvers.py", line 731, in urlconf_module
    return import_module(self.urlconf_name)
  File "/usr/lib/python3.10/importlib/__init__.py", line 126, in import_module
    return _bootstrap._gcd_import(name[level:], package, level)
  File "<frozen importlib._bootstrap>", line 1050, in _gcd_import
  File "<frozen importlib._bootstrap>", line 1027, in _find_and_load
  File "<frozen importlib._bootstrap>", line 1006, in _find_and_load_unlocked
  File "<frozen importlib._bootstrap>", line 688, in _load_unlocked
  File "<frozen importlib._bootstrap_external>", line 883, in exec_module
  File "<frozen importlib._bootstrap>", line 241, in _call_with_frames_removed
  File "/home/ubuntu/SEGroup6/猫猫就诊/Project/./backend/urls.py", line 19, in <module>
    from app01 import views
  File "/home/ubuntu/SEGroup6/猫猫就诊/Project/./app01/views.py", line 7, in <module>
    from rest_framework.views import APIView
ModuleNotFoundError: No module named 'rest_framework'

During handling of the above exception, another exception occurred:

Traceback (most recent call last):
  File "/usr/local/lib/python3.10/dist-packages/django/core/handlers/exception.py", line 55, in inner
    response = get_response(request)
  File "/usr/local/lib/python3.10/dist-packages/django/utils/deprecation.py", line 134, in __call__
    response = response or self.get_response(request)
  File "/usr/local/lib/python3.10/dist-packages/django/core/handlers/exception.py", line 57, in inner
    response = response_for_exception(request, exc)
  File "/usr/local/lib/python3.10/dist-packages/django/core/handlers/exception.py", line 140, in response_for_exception
    response = handle_uncaught_exception(
  File "/usr/local/lib/python3.10/dist-packages/django/core/handlers/exception.py", line 181, in handle_uncaught_exception
    return debug.technical_500_response(request, *exc_info)
  File "/usr/local/lib/python3.10/dist-packages/django/views/debug.py", line 69, in technical_500_response
    html = reporter.get_traceback_html()
  File "/usr/local/lib/python3.10/dist-packages/django/views/debug.py", line 428, in get_traceback_html
    c = Context(self.get_traceback_data(), use_l10n=False)
  File "/usr/local/lib/python3.10/dist-packages/django/views/debug.py", line 411, in get_traceback_data
    c["raising_view_name"] = get_caller(self.request)
  File "/usr/local/lib/python3.10/dist-packages/django/views/debug.py", line 102, in get_caller
    resolver_match = resolve(request.path)
  File "/usr/local/lib/python3.10/dist-packages/django/urls/base.py", line 24, in resolve
    return get_resolver(urlconf).resolve(path)
  File "/usr/local/lib/python3.10/dist-packages/django/urls/resolvers.py", line 686, in resolve
    for pattern in self.url_patterns:
  File "/usr/local/lib/python3.10/dist-packages/django/utils/functional.py", line 47, in __get__
    res = instance.__dict__[self.name] = self.func(instance)
  File "/usr/local/lib/python3.10/dist-packages/django/urls/resolvers.py", line 738, in url_patterns
    patterns = getattr(self.urlconf_module, "urlpatterns", self.urlconf_module)
  File "/usr/local/lib/python3.10/dist-packages/django/utils/functional.py", line 47, in __get__
    res = instance.__dict__[self.name] = self.func(instance)
  File "/usr/local/lib/python3.10/dist-packages/django/urls/resolvers.py", line 731, in urlconf_module
    return import_module(self.urlconf_name)
  File "/usr/lib/python3.10/importlib/__init__.py", line 126, in import_module
    return _bootstrap._gcd_import(name[level:], package, level)
  File "<frozen importlib._bootstrap>", line 1050, in _gcd_import
  File "<frozen importlib._bootstrap>", line 1027, in _find_and_load
  File "<frozen importlib._bootstrap>", line 1006, in _find_and_load_unlocked
  File "<frozen importlib._bootstrap>", line 688, in _load_unlocked
  File "<frozen importlib._bootstrap_external>", line 883, in exec_module
  File "<frozen importlib._bootstrap>", line 241, in _call_with_frames_removed
  File "/home/ubuntu/SEGroup6/猫猫就诊/Project/./backend/urls.py", line 19, in <module>
    from app01 import views
  File "/home/ubuntu/SEGroup6/猫猫就诊/Project/./app01/views.py", line 7, in <module>
    from rest_framework.views import APIView
ModuleNotFoundError: No module named 'rest_framework'

During handling of the above exception, another exception occurred:

Traceback (most recent call last):
  File "/usr/local/lib/python3.10/dist-packages/django/core/handlers/exception.py", line 55, in inner
    response = get_response(request)
  File "/usr/local/lib/python3.10/dist-packages/django/utils/deprecation.py", line 134, in __call__
    response = response or self.get_response(request)
  File "/usr/local/lib/python3.10/dist-packages/django/core/handlers/exception.py", line 57, in inner
    response = response_for_exception(request, exc)
  File "/usr/local/lib/python3.10/dist-packages/django/core/handlers/exception.py", line 140, in response_for_exception
    response = handle_uncaught_exception(
  File "/usr/local/lib/python3.10/dist-packages/django/core/handlers/exception.py", line 181, in handle_uncaught_exception
    return debug.technical_500_response(request, *exc_info)
  File "/usr/local/lib/python3.10/dist-packages/django/views/debug.py", line 69, in technical_500_response
    html = reporter.get_traceback_html()
  File "/usr/local/lib/python3.10/dist-packages/django/views/debug.py", line 428, in get_traceback_html
    c = Context(self.get_traceback_data(), use_l10n=False)
  File "/usr/local/lib/python3.10/dist-packages/django/views/debug.py", line 411, in get_traceback_data
    c["raising_view_name"] = get_caller(self.request)
  File "/usr/local/lib/python3.10/dist-packages/django/views/debug.py", line 102, in get_caller
    resolver_match = resolve(request.path)
  File "/usr/local/lib/python3.10/dist-packages/django/urls/base.py", line 24, in resolve
    return get_resolver(urlconf).resolve(path)
  File "/usr/local/lib/python3.10/dist-packages/django/urls/resolvers.py", line 686, in resolve
    for pattern in self.url_patterns:
  File "/usr/local/lib/python3.10/dist-packages/django/utils/functional.py", line 47, in __get__
    res = instance.__dict__[self.name] = self.func(instance)
  File "/usr/local/lib/python3.10/dist-packages/django/urls/resolvers.py", line 738, in url_patterns
    patterns = getattr(self.urlconf_module, "urlpatterns", self.urlconf_module)
  File "/usr/local/lib/python3.10/dist-packages/django/utils/functional.py", line 47, in __get__
    res = instance.__dict__[self.name] = self.func(instance)
  File "/usr/local/lib/python3.10/dist-packages/django/urls/resolvers.py", line 731, in urlconf_module
    return import_module(self.urlconf_name)
  File "/usr/lib/python3.10/importlib/__init__.py", line 126, in import_module
    return _bootstrap._gcd_import(name[level:], package, level)
  File "<frozen importlib._bootstrap>", line 1050, in _gcd_import
  File "<frozen importlib._bootstrap>", line 1027, in _find_and_load
  File "<frozen importlib._bootstrap>", line 1006, in _find_and_load_unlocked
  File "<frozen importlib._bootstrap>", line 688, in _load_unlocked
  File "<frozen importlib._bootstrap_external>", line 883, in exec_module
  File "<frozen importlib._bootstrap>", line 241, in _call_with_frames_removed
  File "/home/ubuntu/SEGroup6/猫猫就诊/Project/./backend/urls.py", line 19, in <module>
    from app01 import views
  File "/home/ubuntu/SEGroup6/猫猫就诊/Project/./app01/views.py", line 7, in <module>
    from rest_framework.views import APIView
ModuleNotFoundError: No module named 'rest_framework'

During handling of the above exception, another exception occurred:

Traceback (most recent call last):
  File "/usr/local/lib/python3.10/dist-packages/django/core/handlers/exception.py", line 55, in inner
    response = get_response(request)
  File "/usr/local/lib/python3.10/dist-packages/django/utils/deprecation.py", line 134, in __call__
    response = response or self.get_response(request)
  File "/usr/local/lib/python3.10/dist-packages/django/core/handlers/exception.py", line 57, in inner
    response = response_for_exception(request, exc)
  File "/usr/local/lib/python3.10/dist-packages/django/core/handlers/exception.py", line 140, in response_for_exception
    response = handle_uncaught_exception(
  File "/usr/local/lib/python3.10/dist-packages/django/core/handlers/exception.py", line 181, in handle_uncaught_exception
    return debug.technical_500_response(request, *exc_info)
  File "/usr/local/lib/python3.10/dist-packages/django/views/debug.py", line 69, in technical_500_response
    html = reporter.get_traceback_html()
  File "/usr/local/lib/python3.10/dist-packages/django/views/debug.py", line 428, in get_traceback_html
    c = Context(self.get_traceback_data(), use_l10n=False)
  File "/usr/local/lib/python3.10/dist-packages/django/views/debug.py", line 411, in get_traceback_data
    c["raising_view_name"] = get_caller(self.request)
  File "/usr/local/lib/python3.10/dist-packages/django/views/debug.py", line 102, in get_caller
    resolver_match = resolve(request.path)
  File "/usr/local/lib/python3.10/dist-packages/django/urls/base.py", line 24, in resolve
    return get_resolver(urlconf).resolve(path)
  File "/usr/local/lib/python3.10/dist-packages/django/urls/resolvers.py", line 686, in resolve
    for pattern in self.url_patterns:
  File "/usr/local/lib/python3.10/dist-packages/django/utils/functional.py", line 47, in __get__
    res = instance.__dict__[self.name] = self.func(instance)
  File "/usr/local/lib/python3.10/dist-packages/django/urls/resolvers.py", line 738, in url_patterns
    patterns = getattr(self.urlconf_module, "urlpatterns", self.urlconf_module)
  File "/usr/local/lib/python3.10/dist-packages/django/utils/functional.py", line 47, in __get__
    res = instance.__dict__[self.name] = self.func(instance)
  File "/usr/local/lib/python3.10/dist-packages/django/urls/resolvers.py", line 731, in urlconf_module
    return import_module(self.urlconf_name)
  File "/usr/lib/python3.10/importlib/__init__.py", line 126, in import_module
    return _bootstrap._gcd_import(name[level:], package, level)
  File "<frozen importlib._bootstrap>", line 1050, in _gcd_import
  File "<frozen importlib._bootstrap>", line 1027, in _find_and_load
  File "<frozen importlib._bootstrap>", line 1006, in _find_and_load_unlocked
  File "<frozen importlib._bootstrap>", line 688, in _load_unlocked
  File "<frozen importlib._bootstrap_external>", line 883, in exec_module
  File "<frozen importlib._bootstrap>", line 241, in _call_with_frames_removed
  File "/home/ubuntu/SEGroup6/猫猫就诊/Project/./backend/urls.py", line 19, in <module>
    from app01 import views
  File "/home/ubuntu/SEGroup6/猫猫就诊/Project/./app01/views.py", line 7, in <module>
    from rest_framework.views import APIView
ModuleNotFoundError: No module named 'rest_framework'

During handling of the above exception, another exception occurred:

Traceback (most recent call last):
  File "/usr/local/lib/python3.10/dist-packages/django/core/handlers/exception.py", line 55, in inner
    response = get_response(request)
  File "/usr/local/lib/python3.10/dist-packages/django/utils/deprecation.py", line 134, in __call__
    response = response or self.get_response(request)
  File "/usr/local/lib/python3.10/dist-packages/django/core/handlers/exception.py", line 57, in inner
    response = response_for_exception(request, exc)
  File "/usr/local/lib/python3.10/dist-packages/django/core/handlers/exception.py", line 140, in response_for_exception
    response = handle_uncaught_exception(
  File "/usr/local/lib/python3.10/dist-packages/django/core/handlers/exception.py", line 181, in handle_uncaught_exception
    return debug.technical_500_response(request, *exc_info)
  File "/usr/local/lib/python3.10/dist-packages/django/views/debug.py", line 69, in technical_500_response
    html = reporter.get_traceback_html()
  File "/usr/local/lib/python3.10/dist-packages/django/views/debug.py", line 428, in get_traceback_html
    c = Context(self.get_traceback_data(), use_l10n=False)
  File "/usr/local/lib/python3.10/dist-packages/django/views/debug.py", line 411, in get_traceback_data
    c["raising_view_name"] = get_caller(self.request)
  File "/usr/local/lib/python3.10/dist-packages/django/views/debug.py", line 102, in get_caller
    resolver_match = resolve(request.path)
  File "/usr/local/lib/python3.10/dist-packages/django/urls/base.py", line 24, in resolve
    return get_resolver(urlconf).resolve(path)
  File "/usr/local/lib/python3.10/dist-packages/django/urls/resolvers.py", line 686, in resolve
    for pattern in self.url_patterns:
  File "/usr/local/lib/python3.10/dist-packages/django/utils/functional.py", line 47, in __get__
    res = instance.__dict__[self.name] = self.func(instance)
  File "/usr/local/lib/python3.10/dist-packages/django/urls/resolvers.py", line 738, in url_patterns
    patterns = getattr(self.urlconf_module, "urlpatterns", self.urlconf_module)
  File "/usr/local/lib/python3.10/dist-packages/django/utils/functional.py", line 47, in __get__
    res = instance.__dict__[self.name] = self.func(instance)
  File "/usr/local/lib/python3.10/dist-packages/django/urls/resolvers.py", line 731, in urlconf_module
    return import_module(self.urlconf_name)
  File "/usr/lib/python3.10/importlib/__init__.py", line 126, in import_module
    return _bootstrap._gcd_import(name[level:], package, level)
  File "<frozen importlib._bootstrap>", line 1050, in _gcd_import
  File "<frozen importlib._bootstrap>", line 1027, in _find_and_load
  File "<frozen importlib._bootstrap>", line 1006, in _find_and_load_unlocked
  File "<frozen importlib._bootstrap>", line 688, in _load_unlocked
  File "<frozen importlib._bootstrap_external>", line 883, in exec_module
  File "<frozen importlib._bootstrap>", line 241, in _call_with_frames_removed
  File "/home/ubuntu/SEGroup6/猫猫就诊/Project/./backend/urls.py", line 19, in <module>
    from app01 import views
  File "/home/ubuntu/SEGroup6/猫猫就诊/Project/./app01/views.py", line 7, in <module>
    from rest_framework.views import APIView
ModuleNotFoundError: No module named 'rest_framework'

During handling of the above exception, another exception occurred:

Traceback (most recent call last):
  File "/usr/local/lib/python3.10/dist-packages/django/core/handlers/exception.py", line 55, in inner
    response = get_response(request)
  File "/usr/local/lib/python3.10/dist-packages/corsheaders/middleware.py", line 56, in __call__
    result = self.get_response(request)
  File "/usr/local/lib/python3.10/dist-packages/django/core/handlers/exception.py", line 57, in inner
    response = response_for_exception(request, exc)
  File "/usr/local/lib/python3.10/dist-packages/django/core/handlers/exception.py", line 140, in response_for_exception
    response = handle_uncaught_exception(
  File "/usr/local/lib/python3.10/dist-packages/django/core/handlers/exception.py", line 181, in handle_uncaught_exception
    return debug.technical_500_response(request, *exc_info)
  File "/usr/local/lib/python3.10/dist-packages/django/views/debug.py", line 69, in technical_500_response
    html = reporter.get_traceback_html()
  File "/usr/local/lib/python3.10/dist-packages/django/views/debug.py", line 428, in get_traceback_html
    c = Context(self.get_traceback_data(), use_l10n=False)
  File "/usr/local/lib/python3.10/dist-packages/django/views/debug.py", line 411, in get_traceback_data
    c["raising_view_name"] = get_caller(self.request)
  File "/usr/local/lib/python3.10/dist-packages/django/views/debug.py", line 102, in get_caller
    resolver_match = resolve(request.path)
  File "/usr/local/lib/python3.10/dist-packages/django/urls/base.py", line 24, in resolve
    return get_resolver(urlconf).resolve(path)
  File "/usr/local/lib/python3.10/dist-packages/django/urls/resolvers.py", line 686, in resolve
    for pattern in self.url_patterns:
  File "/usr/local/lib/python3.10/dist-packages/django/utils/functional.py", line 47, in __get__
    res = instance.__dict__[self.name] = self.func(instance)
  File "/usr/local/lib/python3.10/dist-packages/django/urls/resolvers.py", line 738, in url_patterns
    patterns = getattr(self.urlconf_module, "urlpatterns", self.urlconf_module)
  File "/usr/local/lib/python3.10/dist-packages/django/utils/functional.py", line 47, in __get__
    res = instance.__dict__[self.name] = self.func(instance)
  File "/usr/local/lib/python3.10/dist-packages/django/urls/resolvers.py", line 731, in urlconf_module
    return import_module(self.urlconf_name)
  File "/usr/lib/python3.10/importlib/__init__.py", line 126, in import_module
    return _bootstrap._gcd_import(name[level:], package, level)
  File "<frozen importlib._bootstrap>", line 1050, in _gcd_import
  File "<frozen importlib._bootstrap>", line 1027, in _find_and_load
  File "<frozen importlib._bootstrap>", line 1006, in _find_and_load_unlocked
  File "<frozen importlib._bootstrap>", line 688, in _load_unlocked
  File "<frozen importlib._bootstrap_external>", line 883, in exec_module
  File "<frozen importlib._bootstrap>", line 241, in _call_with_frames_removed
  File "/home/ubuntu/SEGroup6/猫猫就诊/Project/./backend/urls.py", line 19, in <module>
    from app01 import views
  File "/home/ubuntu/SEGroup6/猫猫就诊/Project/./app01/views.py", line 7, in <module>
    from rest_framework.views import APIView
ModuleNotFoundError: No module named 'rest_framework'

During handling of the above exception, another exception occurred:

Traceback (most recent call last):
  File "/usr/local/lib/python3.10/dist-packages/django/core/handlers/exception.py", line 55, in inner
    response = get_response(request)
  File "/usr/local/lib/python3.10/dist-packages/django/utils/deprecation.py", line 134, in __call__
    response = response or self.get_response(request)
  File "/usr/local/lib/python3.10/dist-packages/django/core/handlers/exception.py", line 57, in inner
    response = response_for_exception(request, exc)
  File "/usr/local/lib/python3.10/dist-packages/django/core/handlers/exception.py", line 140, in response_for_exception
    response = handle_uncaught_exception(
  File "/usr/local/lib/python3.10/dist-packages/django/core/handlers/exception.py", line 181, in handle_uncaught_exception
    return debug.technical_500_response(request, *exc_info)
  File "/usr/local/lib/python3.10/dist-packages/django/views/debug.py", line 69, in technical_500_response
    html = reporter.get_traceback_html()
  File "/usr/local/lib/python3.10/dist-packages/django/views/debug.py", line 428, in get_traceback_html
    c = Context(self.get_traceback_data(), use_l10n=False)
  File "/usr/local/lib/python3.10/dist-packages/django/views/debug.py", line 411, in get_traceback_data
    c["raising_view_name"] = get_caller(self.request)
  File "/usr/local/lib/python3.10/dist-packages/django/views/debug.py", line 102, in get_caller
    resolver_match = resolve(request.path)
  File "/usr/local/lib/python3.10/dist-packages/django/urls/base.py", line 24, in resolve
    return get_resolver(urlconf).resolve(path)
  File "/usr/local/lib/python3.10/dist-packages/django/urls/resolvers.py", line 686, in resolve
    for pattern in self.url_patterns:
  File "/usr/local/lib/python3.10/dist-packages/django/utils/functional.py", line 47, in __get__
    res = instance.__dict__[self.name] = self.func(instance)
  File "/usr/local/lib/python3.10/dist-packages/django/urls/resolvers.py", line 738, in url_patterns
    patterns = getattr(self.urlconf_module, "urlpatterns", self.urlconf_module)
  File "/usr/local/lib/python3.10/dist-packages/django/utils/functional.py", line 47, in __get__
    res = instance.__dict__[self.name] = self.func(instance)
  File "/usr/local/lib/python3.10/dist-packages/django/urls/resolvers.py", line 731, in urlconf_module
    return import_module(self.urlconf_name)
  File "/usr/lib/python3.10/importlib/__init__.py", line 126, in import_module
    return _bootstrap._gcd_import(name[level:], package, level)
  File "<frozen importlib._bootstrap>", line 1050, in _gcd_import
  File "<frozen importlib._bootstrap>", line 1027, in _find_and_load
  File "<frozen importlib._bootstrap>", line 1006, in _find_and_load_unlocked
  File "<frozen importlib._bootstrap>", line 688, in _load_unlocked
  File "<frozen importlib._bootstrap_external>", line 883, in exec_module
  File "<frozen importlib._bootstrap>", line 241, in _call_with_frames_removed
  File "/home/ubuntu/SEGroup6/猫猫就诊/Project/./backend/urls.py", line 19, in <module>
    from app01 import views
  File "/home/ubuntu/SEGroup6/猫猫就诊/Project/./app01/views.py", line 7, in <module>
    from rest_framework.views import APIView
ModuleNotFoundError: No module named 'rest_framework'

During handling of the above exception, another exception occurred:

Traceback (most recent call last):
  File "/usr/local/lib/python3.10/dist-packages/django/core/handlers/exception.py", line 55, in inner
    response = get_response(request)
  File "/usr/local/lib/python3.10/dist-packages/django/utils/deprecation.py", line 134, in __call__
    response = response or self.get_response(request)
  File "/usr/local/lib/python3.10/dist-packages/django/core/handlers/exception.py", line 57, in inner
    response = response_for_exception(request, exc)
  File "/usr/local/lib/python3.10/dist-packages/django/core/handlers/exception.py", line 140, in response_for_exception
    response = handle_uncaught_exception(
  File "/usr/local/lib/python3.10/dist-packages/django/core/handlers/exception.py", line 181, in handle_uncaught_exception
    return debug.technical_500_response(request, *exc_info)
  File "/usr/local/lib/python3.10/dist-packages/django/views/debug.py", line 69, in technical_500_response
    html = reporter.get_traceback_html()
  File "/usr/local/lib/python3.10/dist-packages/django/views/debug.py", line 428, in get_traceback_html
    c = Context(self.get_traceback_data(), use_l10n=False)
  File "/usr/local/lib/python3.10/dist-packages/django/views/debug.py", line 411, in get_traceback_data
    c["raising_view_name"] = get_caller(self.request)
  File "/usr/local/lib/python3.10/dist-packages/django/views/debug.py", line 102, in get_caller
    resolver_match = resolve(request.path)
  File "/usr/local/lib/python3.10/dist-packages/django/urls/base.py", line 24, in resolve
    return get_resolver(urlconf).resolve(path)
  File "/usr/local/lib/python3.10/dist-packages/django/urls/resolvers.py", line 686, in resolve
    for pattern in self.url_patterns:
  File "/usr/local/lib/python3.10/dist-packages/django/utils/functional.py", line 47, in __get__
    res = instance.__dict__[self.name] = self.func(instance)
  File "/usr/local/lib/python3.10/dist-packages/django/urls/resolvers.py", line 738, in url_patterns
    patterns = getattr(self.urlconf_module, "urlpatterns", self.urlconf_module)
  File "/usr/local/lib/python3.10/dist-packages/django/utils/functional.py", line 47, in __get__
    res = instance.__dict__[self.name] = self.func(instance)
  File "/usr/local/lib/python3.10/dist-packages/django/urls/resolvers.py", line 731, in urlconf_module
    return import_module(self.urlconf_name)
  File "/usr/lib/python3.10/importlib/__init__.py", line 126, in import_module
    return _bootstrap._gcd_import(name[level:], package, level)
  File "<frozen importlib._bootstrap>", line 1050, in _gcd_import
  File "<frozen importlib._bootstrap>", line 1027, in _find_and_load
  File "<frozen importlib._bootstrap>", line 1006, in _find_and_load_unlocked
  File "<frozen importlib._bootstrap>", line 688, in _load_unlocked
  File "<frozen importlib._bootstrap_external>", line 883, in exec_module
  File "<frozen importlib._bootstrap>", line 241, in _call_with_frames_removed
  File "/home/ubuntu/SEGroup6/猫猫就诊/Project/./backend/urls.py", line 19, in <module>
    from app01 import views
  File "/home/ubuntu/SEGroup6/猫猫就诊/Project/./app01/views.py", line 7, in <module>
    from rest_framework.views import APIView
ModuleNotFoundError: No module named 'rest_framework'

During handling of the above exception, another exception occurred:

Traceback (most recent call last):
  File "/usr/local/lib/python3.10/dist-packages/django/core/handlers/wsgi.py", line 124, in __call__
    response = self.get_response(request)
  File "/usr/local/lib/python3.10/dist-packages/django/core/handlers/base.py", line 140, in get_response
    response = self._middleware_chain(request)
  File "/usr/local/lib/python3.10/dist-packages/django/core/handlers/exception.py", line 57, in inner
    response = response_for_exception(request, exc)
  File "/usr/local/lib/python3.10/dist-packages/django/core/handlers/exception.py", line 140, in response_for_exception
    response = handle_uncaught_exception(
  File "/usr/local/lib/python3.10/dist-packages/django/core/handlers/exception.py", line 181, in handle_uncaught_exception
    return debug.technical_500_response(request, *exc_info)
  File "/usr/local/lib/python3.10/dist-packages/django/views/debug.py", line 69, in technical_500_response
    html = reporter.get_traceback_html()
  File "/usr/local/lib/python3.10/dist-packages/django/views/debug.py", line 428, in get_traceback_html
    c = Context(self.get_traceback_data(), use_l10n=False)
  File "/usr/local/lib/python3.10/dist-packages/django/views/debug.py", line 411, in get_traceback_data
    c["raising_view_name"] = get_caller(self.request)
  File "/usr/local/lib/python3.10/dist-packages/django/views/debug.py", line 102, in get_caller
    resolver_match = resolve(request.path)
  File "/usr/local/lib/python3.10/dist-packages/django/urls/base.py", line 24, in resolve
    return get_resolver(urlconf).resolve(path)
  File "/usr/local/lib/python3.10/dist-packages/django/urls/resolvers.py", line 686, in resolve
    for pattern in self.url_patterns:
  File "/usr/local/lib/python3.10/dist-packages/django/utils/functional.py", line 47, in __get__
    res = instance.__dict__[self.name] = self.func(instance)
  File "/usr/local/lib/python3.10/dist-packages/django/urls/resolvers.py", line 738, in url_patterns
    patterns = getattr(self.urlconf_module, "urlpatterns", self.urlconf_module)
  File "/usr/local/lib/python3.10/dist-packages/django/utils/functional.py", line 47, in __get__
    res = instance.__dict__[self.name] = self.func(instance)
  File "/usr/local/lib/python3.10/dist-packages/django/urls/resolvers.py", line 731, in urlconf_module
    return import_module(self.urlconf_name)
  File "/usr/lib/python3.10/importlib/__init__.py", line 126, in import_module
    return _bootstrap._gcd_import(name[level:], package, level)
  File "<frozen importlib._bootstrap>", line 1050, in _gcd_import
  File "<frozen importlib._bootstrap>", line 1027, in _find_and_load
  File "<frozen importlib._bootstrap>", line 1006, in _find_and_load_unlocked
  File "<frozen importlib._bootstrap>", line 688, in _load_unlocked
  File "<frozen importlib._bootstrap_external>", line 883, in exec_module
  File "<frozen importlib._bootstrap>", line 241, in _call_with_frames_removed
  File "/home/ubuntu/SEGroup6/猫猫就诊/Project/./backend/urls.py", line 19, in <module>
    from app01 import views
  File "/home/ubuntu/SEGroup6/猫猫就诊/Project/./app01/views.py", line 7, in <module>
    from rest_framework.views import APIView
ModuleNotFoundError: No module named 'rest_framework'
[pid: 28595|app: 0|req: 2/3] 101.42.36.160 () {32 vars in 396 bytes} [Sun May 26 04:00:34 2024] HEAD /api/treatments/list/ => generated 0 bytes in 2300 msecs (HTTP/1.1 500) 0 headers in 0 bytes (0 switches on core 1)
...gracefully killing workers...
Gracefully killing worker 1 (pid: 28594)...
Gracefully killing worker 2 (pid: 28595)...
Gracefully killing worker 3 (pid: 28597)...
Gracefully killing worker 4 (pid: 28598)...
Sun May 26 04:05:21 2024 - uWSGI worker 1 screams: UAAAAAAH my master disconnected: i will kill myself !!!
*** Starting uWSGI 2.0.25.1 (64bit) on [Sun May 26 12:05:45 2024] ***
compiled with version: 11.2.0 on 24 May 2024 14:41:03
os: Linux-5.15.0-86-generic #96-Ubuntu SMP Wed Sep 20 08:23:49 UTC 2023
nodename: VM-8-9-ubuntu
machine: x86_64
clock source: unix
detected number of CPU cores: 2
current working directory: /home/ubuntu/SEGroup6/猫猫就诊/Project
writing pidfile to uwsgi.pid
detected binary path: /usr/local/bin/uwsgi
!!! no internal routing support, rebuild with pcre support !!!
uWSGI running as root, you can use --uid/--gid/--chroot options
*** WARNING: you are running uWSGI as root !!! (use the --uid flag) *** 
chdir() to /home/ubuntu/SEGroup6/猫猫就诊/Project
your processes number limit is 7402
your memory page size is 4096 bytes
detected max file descriptor number: 1024
lock engine: pthread robust mutexes
thunder lock: disabled (you can enable it with --thunder-lock)
uwsgi socket 0 bound to TCP address 127.0.0.1:5000 fd 3
uWSGI running as root, you can use --uid/--gid/--chroot options
*** WARNING: you are running uWSGI as root !!! (use the --uid flag) *** 
Python version: 3.10.12 (main, Jun 11 2023, 05:26:28) [GCC 11.4.0]
Python main interpreter initialized at 0x5643ffce0290
uWSGI running as root, you can use --uid/--gid/--chroot options
*** WARNING: you are running uWSGI as root !!! (use the --uid flag) *** 
python threads support enabled
your server socket listen backlog is limited to 100 connections
your mercy for graceful operations on workers is 60 seconds
mapped 1031270 bytes (1007 KB) for 8 cores
*** Operational MODE: preforking+threaded ***
WSGI app 0 (mountpoint='') ready in 1 seconds on interpreter 0x5643ffce0290 pid: 30995 (default app)
uWSGI running as root, you can use --uid/--gid/--chroot options
*** WARNING: you are running uWSGI as root !!! (use the --uid flag) *** 
*** uWSGI is running in multiple interpreter mode ***
spawned uWSGI master process (pid: 30995)
spawned uWSGI worker 1 (pid: 30999, cores: 2)
spawned uWSGI worker 2 (pid: 31000, cores: 2)
spawned uWSGI worker 3 (pid: 31002, cores: 2)
spawned uWSGI worker 4 (pid: 31004, cores: 2)
[pid: 31000|app: 0|req: 1/1] 219.239.227.188 () {38 vars in 651 bytes} [Sun May 26 04:05:57 2024] GET /api/treatments/list/ => generated 117 bytes in 132 msecs (HTTP/1.1 200) 8 headers in 256 bytes (1 switches on core 0)
[pid: 30999|app: 0|req: 1/2] 219.239.227.188 () {38 vars in 647 bytes} [Sun May 26 04:05:57 2024] GET /api/medicine/list/ => generated 452 bytes in 137 msecs (HTTP/1.1 200) 8 headers in 262 bytes (1 switches on core 0)
